Workbook

Sheet Review
B2: P&G | Test before changing the forecast
B3: 17 quarters. Five business segments. Two information cutoffs.
B4: Decision: remove the unsupported sales cut; do not replace it with a weak coefficient.
B6: Global P&G volume vs US nondurables | C6: Quarters | D6: Slope (pp/pp) | E6: R-squared | F6: Forecast use
B7: ='Model tests'!B15 -> Beauty | C7: ='Model tests'!F15 -> 17 | D7: ='Model tests'!G15 -> 0.65647479 | E7: ='Model tests'!I15 -> 0.25966555 | F7: ='Model tests'!L15 -> Not approved
B8: ='Model tests'!B16 -> Grooming | C8: ='Model tests'!F16 -> 17 | D8: ='Model tests'!G16 -> 0.96197033 | E8: ='Model tests'!I16 -> 0.33991915 | F8: ='Model tests'!L16 -> Not approved
B9: ='Model tests'!B17 -> Health Care | C9: ='Model tests'!F17 -> 17 | D9: ='Model tests'!G17 -> 0.35381963 | E9: ='Model tests'!I17 -> 0.046203344 | F9: ='Model tests'!L17 -> Not approved
B10: ='Model tests'!B18 -> Fabric & Home Care | C10: ='Model tests'!F18 -> 17 | D10: ='Model tests'!G18 -> 1.3609605 | E10: ='Model tests'!I18 -> 0.59687268 | F10: ='Model tests'!L18 -> Not approved
B11: ='Model tests'!B19 -> Baby, Feminine & Family Care | C11: ='Model tests'!F19 -> 17 | D11: ='Model tests'!G19 -> 0.7705192 | E11: ='Model tests'!I19 -> 0.23188987 | F11: ='Model tests'!L19 -> Not approved
B13: Baby, Feminine & Family Care is a combined segment—not Baby Care alone.
B14: Slope measures historical association. It is not a causal sales elasticity.
B15: Market tests use one historical vintage per cutoff; they are not real-time backtests.
B17: New information by 15 May | C17: Period added | D17: Change vs prior month | E17: Action
B18: US personal care prices (NSA) | C18: 2026-04-01 | D18: 0.61655837 | E18: Review; no automatic sales cut
B19: US real nondurable spending (SA) | C19: 2026-03-01 | D19: 0.34757545 | E19: Review; no automatic sales cut
B20: US health/personal store sales (SA) | C20: 2026-04-01 | D20: -0.017453748 | E20: Review; no automatic sales cut
B22: Company actuals stop at March 2026; April–June results are excluded.
B23: April CPI = prices. Retail sales = money spent. Neither equals P&G unit volume.
B24: R-squared describes past co-movement, not forecast accuracy.
B26: Quarter | C26: US nondurable growth | D26: P&G segment volume
B27: ='Matched quarters'!F220 -> 2022-03-31 | C27: ='Matched quarters'!G220 -> 3.5989105 | D27: ='Matched quarters'!H220 -> 2
B28: ='Matched quarters'!F221 -> 2022-06-30 | C28: ='Matched quarters'!G221 -> -0.03796621 | D28: ='Matched quarters'!H221 -> 0
B29: ='Matched quarters'!F222 -> 2022-09-30 | C29: ='Matched quarters'!G222 -> -0.97428175 | D29: ='Matched quarters'!H222 -> -3
B30: ='Matched quarters'!F223 -> 2022-12-31 | C30: ='Matched quarters'!G223 -> -1.7083333 | D30: ='Matched quarters'!H223 -> -6
B31: ='Matched quarters'!F224 -> 2023-03-31 | C31: ='Matched quarters'!G224 -> -0.51383557 | D31: ='Matched quarters'!H224 -> -4
B32: ='Matched quarters'!F225 -> 2023-06-30 | C32: ='Matched quarters'!G225 -> -0.38380426 | D32: ='Matched quarters'!H225 -> 0
B33: ='Matched quarters'!F226 -> 2023-09-30 | C33: ='Matched quarters'!G226 -> 1.1893013 | D33: ='Matched quarters'!H226 -> -3
B34: ='Matched quarters'!F227 -> 2023-12-31 | C34: ='Matched quarters'!G227 -> 2.2255193 | D34: ='Matched quarters'!H227 -> -2
B35: ='Matched quarters'!F228 -> 2024-03-31 | C35: ='Matched quarters'!G228 -> 1.372616 | D35: ='Matched quarters'!H228 -> -3
B36: ='Matched quarters'!F229 -> 2024-06-30 | C36: ='Matched quarters'!G229 -> 2.2805944 | D36: ='Matched quarters'!H229 -> -1
B37: ='Matched quarters'!F230 -> 2024-09-30 | C37: ='Matched quarters'!G230 -> 2.6501995 | D37: ='Matched quarters'!H230 -> -1
B38: ='Matched quarters'!F231 -> 2024-12-31 | C38: ='Matched quarters'!G231 -> 2.7872397 | D38: ='Matched quarters'!H231 -> 4
... B43: ='Matched quarters'!F236 -> 2026-03-31 | C43: ='Matched quarters'!G236 -> 1.5477658 | D43: ='Matched quarters'!H236 -> 3

Sheet Product match
B2: Product matching | Use the right level
B3: Research 11 categories. Financial history covers five global reportable segments.
B5: Product line | C5: P&G reporting segment | D5: Market evidence collected / gap | E5: What it can tell us
B6: Hair Care | C6: Beauty | D6: Hair/dental/shaving CPI | E6: US prices; combined basket
B7: Personal Care | C7: Beauty | D7: Personal care products CPI | E7: US prices; broad basket
B8: Skin Care | C8: Beauty | D8: Cosmetics/bath CPI | E8: US prices; broader products
B9: Grooming | C9: Grooming | D9: Hair/dental/shaving CPI | E9: US prices; combined basket
B10: Oral Care | C10: Health Care | D10: Hair/dental/shaving CPI | E10: US prices; combined basket
B11: Personal Health Care | C11: Health Care | D11: Health/personal store sales | E11: Channel sales; includes other products
B12: Fabric Care | C12: Fabric & Home Care | D12: Household cleaning CPI | E12: US prices; not units sold
B13: Home Care | C13: Fabric & Home Care | D13: Household cleaning CPI | E13: US prices; not units sold
B14: Baby Care | C14: Baby, Feminine & Family Care | D14: No matched diaper quantity series | E14: Do not substitute baby food
B15: Feminine Care | C15: Baby, Feminine & Family Care | D15: No matched quantity series | E15: Do not infer from baby care
B16: Family Care | C16: Baby, Feminine & Family Care | D16: Household paper CPI | E16: US prices; not units sold
B19: Peers are optional: use them to test market vs company-specific explanations.
B20: No peer coefficient is used here. A future peer model must use the same history window.
B21: Match product, geography, units, accounting scope and publication dates first.

Sheet Model tests
B2: Sensitivity tests | Association is not causation
B3: US proxies vs global segments. No coefficient is approved for a sales adjustment.
B5: Segment | C5: P&G measure | D5: Market series | E5: Known by | F5: Quarters | G5: Slope (pp/pp) | H5: Intercept | I5: R-squared | J5: Fit RMSE (pp) | K5: Baseline RMSE | L5: Forecast use
B6: Beauty | C6: organic_volume_growth | D6: PCENDC96 | E6: 2026-04-24 | F6: =COUNT('Matched quarters'!G6:G21) -> 16 | G6: =(SUM('Matched quarters'!K6:K21)-SUM('Matched quarters'!G6:G21)*SUM('Matched quarters'!H6:H21)/F6)/(SUM('Matched quarters'!I6:I21)-SUM('Matched quarters'!G6:G21)^2/F6) -> 0.65552037 | H6: =SUM('Matched quarters'!H6:H21)/F6-G6*SUM('Matched quarters'!G6:G21)/F6 -> -0.94592874 | I6: =(SUM('Matched quarters'!K6:K21)-SUM('Matched quarters'!G6:G21)*SUM('Matched quarters'!H6:H21)/F6)^2/((SUM('Matched quarters'!I6:I21)-SUM('Matched quarters'!G6:G21)^2/F6)*(SUM('Matched quarters'!J6:J21)-SUM('Matched quarters'!H6:H21)^2/F6)) -> 0.37113095 | J6: =SQRT(AVERAGE('Matched quarters'!P14:P21)) -> 1.8329544 | K6: =SQRT(AVERAGE('Matched quarters'!Q14:Q21)) -> 1.5385667 | L6: Not approved
B7: Grooming | C7: organic_volume_growth | D7: PCENDC96 | E7: 2026-04-24 | F7: =COUNT('Matched quarters'!G22:G37) -> 16 | G7: =(SUM('Matched quarters'!K22:K37)-SUM('Matched quarters'!G22:G37)*SUM('Matched quarters'!H22:H37)/F7)/(SUM('Matched quarters'!I22:I37)-SUM('Matched quarters'!G22:G37)^2/F7) -> 0.96234707 | H7: =SUM('Matched quarters'!H22:H37)/F7-G7*SUM('Matched quarters'!G22:G37)/F7 -> -1.5429398 | I7: =(SUM('Matched quarters'!K22:K37)-SUM('Matched quarters'!G22:G37)*SUM('Matched quarters'!H22:H37)/F7)^2/((SUM('Matched quarters'!I22:I37)-SUM('Matched quarters'!G22:G37)^2/F7)*(SUM('Matched quarters'!J22:J37)-SUM('Matched quarters'!H22:H37)^2/F7)) -> 0.35012304 | J7: =SQRT(AVERAGE('Matched quarters'!P30:P37)) -> 2.3862366 | K7: =SQRT(AVERAGE('Matched quarters'!Q30:Q37)) -> 2.5814846 | L7: Not approved
B8: Health Care | C8: organic_volume_growth | D8: PCENDC96 | E8: 2026-04-24 | F8: =COUNT('Matched quarters'!G38:G53) -> 16 | G8: =(SUM('Matched quarters'!K38:K53)-SUM('Matched quarters'!G38:G53)*SUM('Matched quarters'!H38:H53)/F8)/(SUM('Matched quarters'!I38:I53)-SUM('Matched quarters'!G38:G53)^2/F8) -> 0.35409849 | H8: =SUM('Matched quarters'!H38:H53)/F8-G8*SUM('Matched quarters'!G38:G53)/F8 -> -1.1072323 | I8: =(SUM('Matched quarters'!K38:K53)-SUM('Matched quarters'!G38:G53)*SUM('Matched quarters'!H38:H53)/F8)^2/((SUM('Matched quarters'!I38:I53)-SUM('Matched quarters'!G38:G53)^2/F8)*(SUM('Matched quarters'!J38:J53)-SUM('Matched quarters'!H38:H53)^2/F8)) -> 0.047014203 | J8: =SQRT(AVERAGE('Matched quarters'!P46:P53)) -> 2.6781533 | K8: =SQRT(AVERAGE('Matched quarters'!Q46:Q53)) -> 1.8624581 | L8: Not approved
B9: Fabric & Home Care | C9: organic_volume_growth | D9: PCENDC96 | E9: 2026-04-24 | F9: =COUNT('Matched quarters'!G54:G69) -> 16 | G9: =(SUM('Matched quarters'!K54:K69)-SUM('Matched quarters'!G54:G69)*SUM('Matched quarters'!H54:H69)/F9)/(SUM('Matched quarters'!I54:I69)-SUM('Matched quarters'!G54:G69)^2/F9) -> 1.3604792 | H9: =SUM('Matched quarters'!H54:H69)/F9-G9*SUM('Matched quarters'!G54:G69)/F9 -> -2.5929118 | I9: =(SUM('Matched quarters'!K54:K69)-SUM('Matched quarters'!G54:G69)*SUM('Matched quarters'!H54:H69)/F9)^2/((SUM('Matched quarters'!I54:I69)-SUM('Matched quarters'!G54:G69)^2/F9)*(SUM('Matched quarters'!J54:J69)-SUM('Matched quarters'!H54:H69)^2/F9)) -> 0.62224742 | J9: =SQRT(AVERAGE('Matched quarters'!P62:P69)) -> 2.5548722 | K9: =SQRT(AVERAGE('Matched quarters'!Q62:Q69)) -> 1.8853879 | L9: Not approved
B10: Baby, Feminine & Family Care | C10: organic_volume_growth | D10: PCENDC96 | E10: 2026-04-24 | F10: =COUNT('Matched quarters'!G70:G85) -> 16 | G10: =(SUM('Matched quarters'!K70:K85)-SUM('Matched quarters'!G70:G85)*SUM('Matched quarters'!H70:H85)/F10)/(SUM('Matched quarters'!I70:I85)-SUM('Matched quarters'!G70:G85)^2/F10) -> 0.76964966 | H10: =SUM('Matched quarters'!H70:H85)/F10-G10*SUM('Matched quarters'!G70:G85)/F10 -> -2.6840011 | I10: =(SUM('Matched quarters'!K70:K85)-SUM('Matched quarters'!G70:G85)*SUM('Matched quarters'!H70:H85)/F10)^2/((SUM('Matched quarters'!I70:I85)-SUM('Matched quarters'!G70:G85)^2/F10)*(SUM('Matched quarters'!J70:J85)-SUM('Matched quarters'!H70:H85)^2/F10)) -> 0.27636199 | J10: =SQRT(AVERAGE('Matched quarters'!P78:P85)) -> 2.5805522 | K10: =SQRT(AVERAGE('Matched quarters'!Q78:Q85)) -> 2.9487815 | L10: Not approved
B11: Beauty | C11: price_contribution | D11: CUUR0000SEGB | E11: 2026-04-24 | F11: =COUNT('Matched quarters'!G86:G101) -> 16 | G11: =(SUM('Matched quarters'!K86:K101)-SUM('Matched quarters'!G86:G101)*SUM('Matched quarters'!H86:H101)/F11)/(SUM('Matched quarters'!I86:I101)-SUM('Matched quarters'!G86:G101)^2/F11) -> 0.96336109 | H11: =SUM('Matched quarters'!H86:H101)/F11-G11*SUM('Matched quarters'!G86:G101)/F11 -> 1.3471539 | I11: =(SUM('Matched quarters'!K86:K101)-SUM('Matched quarters'!G86:G101)*SUM('Matched quarters'!H86:H101)/F11)^2/((SUM('Matched quarters'!I86:I101)-SUM('Matched quarters'!G86:G101)^2/F11)*(SUM('Matched quarters'!J86:J101)-SUM('Matched quarters'!H86:H101)^2/F11)) -> 0.84290373 | J11: =SQRT(AVERAGE('Matched quarters'!P94:P101)) -> 1.3463739 | K11: =SQRT(AVERAGE('Matched quarters'!Q94:Q101)) -> 1.9764235 | L11: Not approved
B12: Grooming | C12: price_contribution | D12: CUUR0000SEGB | E12: 2026-04-24 | F12: =COUNT('Matched quarters'!G102:G117) -> 16 | G12: =(SUM('Matched quarters'!K102:K117)-SUM('Matched quarters'!G102:G117)*SUM('Matched quarters'!H102:H117)/F12)/(SUM('Matched quarters'!I102:I117)-SUM('Matched quarters'!G102:G117)^2/F12) -> 1.1270646 | H12: =SUM('Matched quarters'!H102:H117)/F12-G12*SUM('Matched quarters'!G102:G117)/F12 -> 2.4576334 | I12: =(SUM('Matched quarters'!K102:K117)-SUM('Matched quarters'!G102:G117)*SUM('Matched quarters'!H102:H117)/F12)^2/((SUM('Matched quarters'!I102:I117)-SUM('Matched quarters'!G102:G117)^2/F12)*(SUM('Matched quarters'!J102:J117)-SUM('Matched quarters'!H102:H117)^2/F12)) -> 0.80021182 | J12: =SQRT(AVERAGE('Matched quarters'!P110:P117)) -> 2.1749551 | K12: =SQRT(AVERAGE('Matched quarters'!Q110:Q117)) -> 3.4629738 | L12: Not approved
B13: Beauty | C13: organic_sales_growth | D13: RSHPCS | E13: 2026-04-24 | F13: =COUNT('Matched quarters'!G118:G134) -> 17 | G13: =(SUM('Matched quarters'!K118:K134)-SUM('Matched quarters'!G118:G134)*SUM('Matched quarters'!H118:H134)/F13)/(SUM('Matched quarters'!I118:I134)-SUM('Matched quarters'!G118:G134)^2/F13) -> 0.10895444 | H13: =SUM('Matched quarters'!H118:H134)/F13-G13*SUM('Matched quarters'!G118:G134)/F13 -> 2.9295212 | I13: =(SUM('Matched quarters'!K118:K134)-SUM('Matched quarters'!G118:G134)*SUM('Matched quarters'!H118:H134)/F13)^2/((SUM('Matched quarters'!I118:I134)-SUM('Matched quarters'!G118:G134)^2/F13)*(SUM('Matched quarters'!J118:J134)-SUM('Matched quarters'!H118:H134)^2/F13)) -> 0.0092390824 | J13: =SQRT(AVERAGE('Matched quarters'!P126:P134)) -> 3.0905804 | K13: =SQRT(AVERAGE('Matched quarters'!Q126:Q134)) -> 3.0196118 | L13: Not approved
B14: Health Care | C14: organic_sales_growth | D14: RSHPCS | E14: 2026-04-24 | F14: =COUNT('Matched quarters'!G135:G151) -> 17 | G14: =(SUM('Matched quarters'!K135:K151)-SUM('Matched quarters'!G135:G151)*SUM('Matched quarters'!H135:H151)/F14)/(SUM('Matched quarters'!I135:I151)-SUM('Matched quarters'!G135:G151)^2/F14) -> 0.062652357 | H14: =SUM('Matched quarters'!H135:H151)/F14-G14*SUM('Matched quarters'!G135:G151)/F14 -> 5.0668081 | I14: =(SUM('Matched quarters'!K135:K151)-SUM('Matched quarters'!G135:G151)*SUM('Matched quarters'!H135:H151)/F14)^2/((SUM('Matched quarters'!I135:I151)-SUM('Matched quarters'!G135:G151)^2/F14)*(SUM('Matched quarters'!J135:J151)-SUM('Matched quarters'!H135:H151)^2/F14)) -> 0.0017920341 | J14: =SQRT(AVERAGE('Matched quarters'!P143:P151)) -> 4.7260407 | K14: =SQRT(AVERAGE('Matched quarters'!Q143:Q151)) -> 1.8333333 | L14: Not approved
B15: Beauty | C15: organic_volume_growth | D15: PCENDC96 | E15: 2026-05-15 | F15: =COUNT('Matched quarters'!G152:G168) -> 17 | G15: =(SUM('Matched quarters'!K152:K168)-SUM('Matched quarters'!G152:G168)*SUM('Matched quarters'!H152:H168)/F15)/(SUM('Matched quarters'!I152:I168)-SUM('Matched quarters'!G152:G168)^2/F15) -> 0.65647479 | H15: =SUM('Matched quarters'!H152:H168)/F15-G15*SUM('Matched quarters'!G152:G168)/F15 -> -0.65731888 | I15: =(SUM('Matched quarters'!K152:K168)-SUM('Matched quarters'!G152:G168)*SUM('Matched quarters'!H152:H168)/F15)^2/((SUM('Matched quarters'!I152:I168)-SUM('Matched quarters'!G152:G168)^2/F15)*(SUM('Matched quarters'!J152:J168)-SUM('Matched quarters'!H152:H168)^2/F15)) -> 0.25966555 | J15: =SQRT(AVERAGE('Matched quarters'!P160:P168)) -> 2.3850427 | K15: =SQRT(AVERAGE('Matched quarters'!Q160:Q168)) -> 1.7159384 | L15: Not approved
B16: Grooming | C16: organic_volume_growth | D16: PCENDC96 | E16: 2026-05-15 | F16: =COUNT('Matched quarters'!G169:G185) -> 17 | G16: =(SUM('Matched quarters'!K169:K185)-SUM('Matched quarters'!G169:G185)*SUM('Matched quarters'!H169:H185)/F16)/(SUM('Matched quarters'!I169:I185)-SUM('Matched quarters'!G169:G185)^2/F16) -> 0.96197033 | H16: =SUM('Matched quarters'!H169:H185)/F16-G16*SUM('Matched quarters'!G169:G185)/F16 -> -1.6568629 | I16: =(SUM('Matched quarters'!K169:K185)-SUM('Matched quarters'!G169:G185)*SUM('Matched quarters'!H169:H185)/F16)^2/((SUM('Matched quarters'!I169:I185)-SUM('Matched quarters'!G169:G185)^2/F16)*(SUM('Matched quarters'!J169:J185)-SUM('Matched quarters'!H169:H185)^2/F16)) -> 0.33991915 | J16: =SQRT(AVERAGE('Matched quarters'!P177:P185)) -> 2.3414632 | K16: =SQRT(AVERAGE('Matched quarters'!Q177:Q185)) -> 2.5027762 | L16: Not approved
B17: Health Care | C17: organic_volume_growth | D17: PCENDC96 | E17: 2026-05-15 | F17: =COUNT('Matched quarters'!G186:G202) -> 17 | G17: =(SUM('Matched quarters'!K186:K202)-SUM('Matched quarters'!G186:G202)*SUM('Matched quarters'!H186:H202)/F17)/(SUM('Matched quarters'!I186:I202)-SUM('Matched quarters'!G186:G202)^2/F17) -> 0.35381963 | H17: =SUM('Matched quarters'!H186:H202)/F17-G17*SUM('Matched quarters'!G186:G202)/F17 -> -1.1915578 | I17: =(SUM('Matched quarters'!K186:K202)-SUM('Matched quarters'!G186:G202)*SUM('Matched quarters'!H186:H202)/F17)^2/((SUM('Matched quarters'!I186:I202)-SUM('Matched quarters'!G186:G202)^2/F17)*(SUM('Matched quarters'!J186:J202)-SUM('Matched quarters'!H186:H202)^2/F17)) -> 0.046203344 | J17: =SQRT(AVERAGE('Matched quarters'!P194:P202)) -> 2.5702578 | K17: =SQRT(AVERAGE('Matched quarters'!Q194:Q202)) -> 1.7638342 | L17: Not approved
B18: Fabric & Home Care | C18: organic_volume_growth | D18: PCENDC96 | E18: 2026-05-15 | F18: =COUNT('Matched quarters'!G203:G219) -> 17 | G18: =(SUM('Matched quarters'!K203:K219)-SUM('Matched quarters'!G203:G219)*SUM('Matched quarters'!H203:H219)/F18)/(SUM('Matched quarters'!I203:I219)-SUM('Matched quarters'!G203:G219)^2/F18) -> 1.3609605 | H18: =SUM('Matched quarters'!H203:H219)/F18-G18*SUM('Matched quarters'!G203:G219)/F18 -> -2.4473462 | I18: =(SUM('Matched quarters'!K203:K219)-SUM('Matched quarters'!G203:G219)*SUM('Matched quarters'!H203:H219)/F18)^2/((SUM('Matched quarters'!I203:I219)-SUM('Matched quarters'!G203:G219)^2/F18)*(SUM('Matched quarters'!J203:J219)-SUM('Matched quarters'!H203:H219)^2/F18)) -> 0.59687268 | J18: =SQRT(AVERAGE('Matched quarters'!P211:P219)) -> 2.5474428 | K18: =SQRT(AVERAGE('Matched quarters'!Q211:Q219)) -> 1.9632032 | L18: Not approved
B19: Baby, Feminine & Family Care | C19: organic_volume_growth | D19: PCENDC96 | E19: 2026-05-15 | F19: =COUNT('Matched quarters'!G220:G236) -> 17 | G19: =(SUM('Matched quarters'!K220:K236)-SUM('Matched quarters'!G220:G236)*SUM('Matched quarters'!H220:H236)/F19)/(SUM('Matched quarters'!I220:I236)-SUM('Matched quarters'!G220:G236)^2/F19) -> 0.7705192 | H19: =SUM('Matched quarters'!H220:H236)/F19-G19*SUM('Matched quarters'!G220:G236)/F19 -> -2.421059 | I19: =(SUM('Matched quarters'!K220:K236)-SUM('Matched quarters'!G220:G236)*SUM('Matched quarters'!H220:H236)/F19)^2/((SUM('Matched quarters'!I220:I236)-SUM('Matched quarters'!G220:G236)^2/F19)*(SUM('Matched quarters'!J220:J236)-SUM('Matched quarters'!H220:H236)^2/F19)) -> 0.23188987 | J19: =SQRT(AVERAGE('Matched quarters'!P228:P236)) -> 2.8569394 | K19: =SQRT(AVERAGE('Matched quarters'!Q228:Q236)) -> 3.1993923 | L19: Not approved
B20: Beauty | C20: price_contribution | D20: CUUR0000SEGB | E20: 2026-05-15 | F20: =COUNT('Matched quarters'!G237:G252) -> 16 | G20: =(SUM('Matched quarters'!K237:K252)-SUM('Matched quarters'!G237:G252)*SUM('Matched quarters'!H237:H252)/F20)/(SUM('Matched quarters'!I237:I252)-SUM('Matched quarters'!G237:G252)^2/F20) -> 0.96336109 | H20: =SUM('Matched quarters'!H237:H252)/F20-G20*SUM('Matched quarters'!G237:G252)/F20 -> 1.3471539 | I20: =(SUM('Matched quarters'!K237:K252)-SUM('Matched quarters'!G237:G252)*SUM('Matched quarters'!H237:H252)/F20)^2/((SUM('Matched quarters'!I237:I252)-SUM('Matched quarters'!G237:G252)^2/F20)*(SUM('Matched quarters'!J237:J252)-SUM('Matched quarters'!H237:H252)^2/F20)) -> 0.84290373 | J20: =SQRT(AVERAGE('Matched quarters'!P245:P252)) -> 1.3463739 | K20: =SQRT(AVERAGE('Matched quarters'!Q245:Q252)) -> 1.9764235 | L20: Not approved
B21: Grooming | C21: price_contribution | D21: CUUR0000SEGB | E21: 2026-05-15 | F21: =COUNT('Matched quarters'!G253:G268) -> 16 | G21: =(SUM('Matched quarters'!K253:K268)-SUM('Matched quarters'!G253:G268)*SUM('Matched quarters'!H253:H268)/F21)/(SUM('Matched quarters'!I253:I268)-SUM('Matched quarters'!G253:G268)^2/F21) -> 1.1270646 | H21: =SUM('Matched quarters'!H253:H268)/F21-G21*SUM('Matched quarters'!G253:G268)/F21 -> 2.4576334 | I21: =(SUM('Matched quarters'!K253:K268)-SUM('Matched quarters'!G253:G268)*SUM('Matched quarters'!H253:H268)/F21)^2/((SUM('Matched quarters'!I253:I268)-SUM('Matched quarters'!G253:G268)^2/F21)*(SUM('Matched quarters'!J253:J268)-SUM('Matched quarters'!H253:H268)^2/F21)) -> 0.80021182 | J21: =SQRT(AVERAGE('Matched quarters'!P261:P268)) -> 2.1749551 | K21: =SQRT(AVERAGE('Matched quarters'!Q261:Q268)) -> 3.4629738 | L21: Not approved
B22: Beauty | C22: organic_sales_growth | D22: RSHPCS | E22: 2026-05-15 | F22: =COUNT('Matched quarters'!G269:G285) -> 17 | G22: =(SUM('Matched quarters'!K269:K285)-SUM('Matched quarters'!G269:G285)*SUM('Matched quarters'!H269:H285)/F22)/(SUM('Matched quarters'!I269:I285)-SUM('Matched quarters'!G269:G285)^2/F22) -> 0.11163568 | H22: =SUM('Matched quarters'!H269:H285)/F22-G22*SUM('Matched quarters'!G269:G285)/F22 -> 2.9115216 | I22: =(SUM('Matched quarters'!K269:K285)-SUM('Matched quarters'!G269:G285)*SUM('Matched quarters'!H269:H285)/F22)^2/((SUM('Matched quarters'!I269:I285)-SUM('Matched quarters'!G269:G285)^2/F22)*(SUM('Matched quarters'!J269:J285)-SUM('Matched quarters'!H269:H285)^2/F22)) -> 0.0097007108 | J22: =SQRT(AVERAGE('Matched quarters'!P277:P285)) -> 3.0876523 | K22: =SQRT(AVERAGE('Matched quarters'!Q277:Q285)) -> 3.0196118 | L22: Not approved
B23: Health Care | C23: organic_sales_growth | D23: RSHPCS | E23: 2026-05-15 | F23: =COUNT('Matched quarters'!G286:G302) -> 17 | G23: =(SUM('Matched quarters'!K286:K302)-SUM('Matched quarters'!G286:G302)*SUM('Matched quarters'!H286:H302)/F23)/(SUM('Matched quarters'!I286:I302)-SUM('Matched quarters'!G286:G302)^2/F23) -> 0.047002303 | H23: =SUM('Matched quarters'!H286:H302)/F23-G23*SUM('Matched quarters'!G286:G302)/F23 -> 5.1516126 | I23: =(SUM('Matched quarters'!K286:K302)-SUM('Matched quarters'!G286:G302)*SUM('Matched quarters'!H286:H302)/F23)^2/((SUM('Matched quarters'!I286:I302)-SUM('Matched quarters'!G286:G302)^2/F23)*(SUM('Matched quarters'!J286:J302)-SUM('Matched quarters'!H286:H302)^2/F23)) -> 0.0010087144 | J23: =SQRT(AVERAGE('Matched quarters'!P294:P302)) -> 4.7316834 | K23: =SQRT(AVERAGE('Matched quarters'!Q294:Q302)) -> 1.8333333 | L23: Not approved

Sheet Matched quarters
B2: Quarterly pairs | Company and market
B5: Segment | C5: Company measure | D5: Market series | E5: Known by | F5: Quarter ended | G5: Market YoY % | H5: P&G % | I5: Market squared | J5: P&G squared | K5: Cross product | L5: Fitted P&G % | M5: Residual pp | N5: Rolling fit % | O5: Trailing-four % | P5: Fit error squared | Q5: Baseline error squared
B6: Beauty | C6: organic_volume_growth | D6: PCENDC96 | E6: 2026-04-24 | F6: 2022-03-31 | G6: ='Quarterly market'!G40 -> 3.5989105 | H6: ='PG history'!G6 -> -1 | I6: =G6*G6 -> 12.952157 | J6: =H6*H6 -> 1 | K6: =G6*H6 -> -3.5989105 | L6: ='Model tests'!H6+'Model tests'!G6*G6 -> 1.4132304 | M6: =H6-L6 -> -2.4132304
B7: Beauty | C7: organic_volume_growth | D7: PCENDC96 | E7: 2026-04-24 | F7: 2022-06-30 | G7: ='Quarterly market'!G41 -> -0.03796621 | H7: ='PG history'!G13 -> -2 | I7: =G7*G7 -> 0.0014414331 | J7: =H7*H7 -> 4 | K7: =G7*H7 -> 0.07593242 | L7: ='Model tests'!H6+'Model tests'!G6*G7 -> -0.97081637 | M7: =H7-L7 -> -1.0291836
B8: Beauty | C8: organic_volume_growth | D8: PCENDC96 | E8: 2026-04-24 | F8: 2022-09-30 | G8: ='Quarterly market'!G42 -> -0.97428175 | H8: ='PG history'!G20 -> -1 | I8: =G8*G8 -> 0.94922494 | J8: =H8*H8 -> 1 | K8: =G8*H8 -> 0.97428175 | L8: ='Model tests'!H6+'Model tests'!G6*G8 -> -1.5845903 | M8: =H8-L8 -> 0.58459028
B9: Beauty | C9: organic_volume_growth | D9: PCENDC96 | E9: 2026-04-24 | F9: 2022-12-31 | G9: ='Quarterly market'!G43 -> -1.7083333 | H9: ='PG history'!G27 -> -4 | I9: =G9*G9 -> 2.9184028 | J9: =H9*H9 -> 16 | K9: =G9*H9 -> 6.8333333 | L9: ='Model tests'!H6+'Model tests'!G6*G9 -> -2.065776 | M9: =H9-L9 -> -1.934224
B10: Beauty | C10: organic_volume_growth | D10: PCENDC96 | E10: 2026-04-24 | F10: 2023-03-31 | G10: ='Quarterly market'!G44 -> -0.51383557 | H10: ='PG history'!G34 -> 0 | I10: =G10*G10 -> 0.264027 | J10: =H10*H10 -> 0 | K10: =G10*H10 -> 0 | L10: ='Model tests'!H6+'Model tests'!G6*G10 -> -1.2827584 | M10: =H10-L10 -> 1.2827584
B11: Beauty | C11: organic_volume_growth | D11: PCENDC96 | E11: 2026-04-24 | F11: 2023-06-30 | G11: ='Quarterly market'!G45 -> -0.38380426 | H11: ='PG history'!G41 -> -1 | I11: =G11*G11 -> 0.14730571 | J11: =H11*H11 -> 1 | K11: =G11*H11 -> 0.38380426 | L11: ='Model tests'!H6+'Model tests'!G6*G11 -> -1.1975203 | M11: =H11-L11 -> 0.19752025
B12: Beauty | C12: organic_volume_growth | D12: PCENDC96 | E12: 2026-04-24 | F12: 2023-09-30 | G12: ='Quarterly market'!G46 -> 1.1893013 | H12: ='PG history'!G48 -> 0 | I12: =G12*G12 -> 1.4144376 | J12: =H12*H12 -> 0 | K12: =G12*H12 -> 0 | L12: ='Model tests'!H6+'Model tests'!G6*G12 -> -0.1663175 | M12: =H12-L12 -> 0.1663175
B13: Beauty | C13: organic_volume_growth | D13: PCENDC96 | E13: 2026-04-24 | F13: 2023-12-31 | G13: ='Quarterly market'!G47 -> 2.2255193 | H13: ='PG history'!G55 -> -1 | I13: =G13*G13 -> 4.9529361 | J13: =H13*H13 -> 1 | K13: =G13*H13 -> -2.2255193 | L13: ='Model tests'!H6+'Model tests'!G6*G13 -> 0.51294448 | M13: =H13-L13 -> -1.5129445
B14: Beauty | C14: organic_volume_growth | D14: PCENDC96 | E14: 2026-04-24 | F14: 2024-03-31 | G14: ='Quarterly market'!G48 -> 1.372616 | H14: ='PG history'!G62 -> 1 | I14: =G14*G14 -> 1.8840747 | J14: =H14*H14 -> 1 | K14: =G14*H14 -> 1.372616 | L14: ='Model tests'!H6+'Model tests'!G6*G14 -> -0.046150994 | M14: =H14-L14 -> 1.046151 | N14: =AVERAGE(H6:H13)+((SUM(K6:K13)-SUM(G6:G13)*SUM(H6:H13)/COUNT(G6:G13))/(SUM(I6:I13)-SUM(G6:G13)^2/COUNT(G6:G13)))*(G14-AVERAGE(G6:G13)) -> -0.96384867 | O14: =AVERAGE(H10:H13) -> -0.5 | P14: =(H14-N14)^2 -> 3.8567016 | Q14: =(H14-O14)^2 -> 2.25
B15: Beauty | C15: organic_volume_growth | D15: PCENDC96 | E15: 2026-04-24 | F15: 2024-06-30 | G15: ='Quarterly market'!G49 -> 2.2805944 | H15: ='PG history'!G69 -> 1 | I15: =G15*G15 -> 5.2011107 | J15: =H15*H15 -> 1 | K15: =G15*H15 -> 2.2805944 | L15: ='Model tests'!H6+'Model tests'!G6*G15 -> 0.54904732 | M15: =H15-L15 -> 0.45095268 | N15: =AVERAGE(H6:H14)+((SUM(K6:K14)-SUM(G6:G14)*SUM(H6:H14)/COUNT(G6:G14))/(SUM(I6:I14)-SUM(G6:G14)^2/COUNT(G6:G14)))*(G15-AVERAGE(G6:G14)) -> -0.34539719 | O15: =AVERAGE(H11:H14) -> -0.25 | P15: =(H15-N15)^2 -> 1.8100936 | Q15: =(H15-O15)^2 -> 1.5625
B16: Beauty | C16: organic_volume_growth | D16: PCENDC96 | E16: 2026-04-24 | F16: 2024-09-30 | G16: ='Quarterly market'!G50 -> 2.6501995 | H16: ='PG history'!G76 -> 0 | I16: =G16*G16 -> 7.0235576 | J16: =H16*H16 -> 0 | K16: =G16*H16 -> 0 | L16: ='Model tests'!H6+'Model tests'!G6*G16 -> 0.79133103 | M16: =H16-L16 -> -0.79133103 | N16: =AVERAGE(H6:H15)+((SUM(K6:K15)-SUM(G6:G15)*SUM(H6:H15)/COUNT(G6:G15))/(SUM(I6:I15)-SUM(G6:G15)^2/COUNT(G6:G15)))*(G16-AVERAGE(G6:G15)) -> 0.087697667 | O16: =AVERAGE(H12:H15) -> 0.25 | P16: =(H16-N16)^2 -> 0.0076908808 | Q16: =(H16-O16)^2 -> 0.0625
B17: Beauty | C17: organic_volume_growth | D17: PCENDC96 | E17: 2026-04-24 | F17: 2024-12-31 | G17: ='Quarterly market'!G51 -> 2.7872397 | H17: ='PG history'!G83 -> 0 | I17: =G17*G17 -> 7.7687052 | J17: =H17*H17 -> 0 | K17: =G17*H17 -> 0 | L17: ='Model tests'!H6+'Model tests'!G6*G17 -> 0.88116366 | M17: =H17-L17 -> -0.88116366 | N17: =AVERAGE(H6:H16)+((SUM(K6:K16)-SUM(G6:G16)*SUM(H6:H16)/COUNT(G6:G16))/(SUM(I6:I16)-SUM(G6:G16)^2/COUNT(G6:G16)))*(G17-AVERAGE(G6:G16)) -> 0.1321239 | O17: =AVERAGE(H13:H16) -> 0.25 | P17: =(H17-N17)^2 -> 0.017456725 | Q17: =(H17-O17)^2 -> 0.0625
B18: Beauty | C18: organic_volume_growth | D18: PCENDC96 | E18: 2026-04-24 | F18: 2025-03-31 | G18: ='Quarterly market'!G52 -> 3.7498513 | H18: ='PG history'!G90 -> 1 | I18: =G18*G18 -> 14.061385 | J18: =H18*H18 -> 1 | K18: =G18*H18 -> 3.7498513 | L18: ='Model tests'!H6+'Model tests'!G6*G18 -> 1.5121752 | M18: =H18-L18 -> -0.51217516 | N18: =AVERAGE(H6:H17)+((SUM(K6:K17)-SUM(G6:G17)*SUM(H6:H17)/COUNT(G6:G17))/(SUM(I6:I17)-SUM(G6:G17)^2/COUNT(G6:G17)))*(G18-AVERAGE(G6:G17)) -> 0.53600723 | O18: =AVERAGE(H14:H17) -> 0.5 | P18: =(H18-N18)^2 -> 0.21528929 | Q18: =(H18-O18)^2 -> 0.25
B19: Beauty | C19: organic_volume_growth | D19: PCENDC96 | E19: 2026-04-24 | F19: 2025-06-30 | G19: ='Quarterly market'!G53 -> 3.2332745 | H19: ='PG history'!G97 -> 1 | I19: =G19*G19 -> 10.454064 | J19: =H19*H19 -> 1 | K19: =G19*H19 -> 3.2332745 | L19: ='Model tests'!H6+'Model tests'!G6*G19 -> 1.1735485 | M19: =H19-L19 -> -0.17354853 | N19: =AVERAGE(H6:H18)+((SUM(K6:K18)-SUM(G6:G18)*SUM(H6:H18)/COUNT(G6:G18))/(SUM(I6:I18)-SUM(G6:G18)^2/COUNT(G6:G18)))*(G19-AVERAGE(G6:G18)) -> 0.40104061 | O19: =AVERAGE(H15:H18) -> 0.5 | P19: =(H19-N19)^2 -> 0.35875235 | Q19: =(H19-O19)^2 -> 0.25
B20: Beauty | C20: organic_volume_growth | D20: PCENDC96 | E20: 2026-04-24 | F20: 2025-09-30 | G20: ='Quarterly market'!G54 -> 2.9967231 | H20: ='PG history'!G104 -> 4 | I20: =G20*G20 -> 8.9803493 | J20: =H20*H20 -> 16 | K20: =G20*H20 -> 11.986892 | L20: ='Model tests'!H6+'Model tests'!G6*G20 -> 1.0184843 | M20: =H20-L20 -> 2.9815157 | N20: =AVERAGE(H6:H19)+((SUM(K6:K19)-SUM(G6:G19)*SUM(H6:H19)/COUNT(G6:G19))/(SUM(I6:I19)-SUM(G6:G19)^2/COUNT(G6:G19)))*(G20-AVERAGE(G6:G19)) -> 0.3731275 | O20: =AVERAGE(H16:H19) -> 0.5 | P20: =(H20-N20)^2 -> 13.154204 | Q20: =(H20-O20)^2 -> 12.25
B21: Beauty | C21: organic_volume_growth | D21: PCENDC96 | E21: 2026-04-24 | F21: 2025-12-31 | G21: ='Quarterly market'!G55 -> 2.1478109 | H21: ='PG history'!G111 -> 3 | I21: =G21*G21 -> 4.6130916 | J21: =H21*H21 -> 9 | K21: =G21*H21 -> 6.4434327 | L21: ='Model tests'!H6+'Model tests'!G6*G21 -> 0.46200503 | M21: =H21-L21 -> 2.537995 | N21: =AVERAGE(H6:H20)+((SUM(K6:K20)-SUM(G6:G20)*SUM(H6:H20)/COUNT(G6:G20))/(SUM(I6:I20)-SUM(G6:G20)^2/COUNT(G6:G20)))*(G21-AVERAGE(G6:G20)) -> 0.26914172 | O21: =AVERAGE(H17:H20) -> 1.5 | P21: =(H21-N21)^2 -> 7.457587 | Q21: =(H21-O21)^2 -> 2.25
B22: Grooming | C22: organic_volume_growth | D22: PCENDC96 | E22: 2026-04-24 | F22: 2022-03-31 | G22: ='Quarterly market'!G40 -> 3.5989105 | H22: ='PG history'!G7 -> 1 | I22: =G22*G22 -> 12.952157 | J22: =H22*H22 -> 1 | K22: =G22*H22 -> 3.5989105 | L22: ='Model tests'!H7+'Model tests'!G7*G22 -> 1.9204612 | M22: =H22-L22 -> -0.92046115
B23: Grooming | C23: organic_volume_growth | D23: PCENDC96 | E23: 2026-04-24 | F23: 2022-06-30 | G23: ='Quarterly market'!G41 -> -0.03796621 | H23: ='PG history'!G14 -> -2 | I23: =G23*G23 -> 0.0014414331 | J23: =H23*H23 -> 4 | K23: =G23*H23 -> 0.07593242 | L23: ='Model tests'!H7+'Model tests'!G7*G23 -> -1.5794765 | M23: =H23-L23 -> -0.42052352
B24: Grooming | C24: organic_volume_growth | D24: PCENDC96 | E24: 2026-04-24 | F24: 2022-09-30 | G24: ='Quarterly market'!G42 -> -0.97428175 | H24: ='PG history'!G21 -> 1 | I24: =G24*G24 -> 0.94922494 | J24: =H24*H24 -> 1 | K24: =G24*H24 -> -0.97428175 | L24: ='Model tests'!H7+'Model tests'!G7*G24 -> -2.480537 | M24: =H24-L24 -> 3.480537
B25: Grooming | C25: organic_volume_growth | D25: PCENDC96 | E25: 2026-04-24 | F25: 2022-12-31 | G25: ='Quarterly market'!G43 -> -1.7083333 | H25: ='PG history'!G28 -> -8 | I25: =G25*G25 -> 2.9184028 | J25: =H25*H25 -> 64 | K25: =G25*H25 -> 13.666667 | L25: ='Model tests'!H7+'Model tests'!G7*G25 -> -3.1869494 | M25: =H25-L25 -> -4.8130506
B26: Grooming | C26: organic_volume_growth | D26: PCENDC96 | E26: 2026-04-24 | F26: 2023-03-31 | G26: ='Quarterly market'!G44 -> -0.51383557 | H26: ='PG history'!G35 -> -1 | I26: =G26*G26 -> 0.264027 | J26: =H26*H26 -> 1 | K26: =G26*H26 -> 0.51383557 | L26: ='Model tests'!H7+'Model tests'!G7*G26 -> -2.037428 | M26: =H26-L26 -> 1.037428
B27: Grooming | C27: organic_volume_growth | D27: PCENDC96 | E27: 2026-04-24 | F27: 2023-06-30 | G27: ='Quarterly market'!G45 -> -0.38380426 | H27: ='PG history'!G42 -> -1 | I27: =G27*G27 -> 0.14730571 | J27: =H27*H27 -> 1 | K27: =G27*H27 -> 0.38380426 | L27: ='Model tests'!H7+'Model tests'!G7*G27 -> -1.9122927 | M27: =H27-L27 -> 0.91229271
B28: Grooming | C28: organic_volume_growth | D28: PCENDC96 | E28: 2026-04-24 | F28: 2023-09-30 | G28: ='Quarterly market'!G46 -> 1.1893013 | H28: ='PG history'!G49 -> -2 | I28: =G28*G28 -> 1.4144376 | J28: =H28*H28 -> 4 | K28: =G28*H28 -> -2.3786026 | L28: ='Model tests'!H7+'Model tests'!G7*G28 -> -0.39841917 | M28: =H28-L28 -> -1.6015808
B29: Grooming | C29: organic_volume_growth | D29: PCENDC96 | E29: 2026-04-24 | F29: 2023-12-31 | G29: ='Quarterly market'!G47 -> 2.2255193 | H29: ='PG history'!G56 -> 1 | I29: =G29*G29 -> 4.9529361 | J29: =H29*H29 -> 1 | K29: =G29*H29 -> 2.2255193 | L29: ='Model tests'!H7+'Model tests'!G7*G29 -> 0.59878216 | M29: =H29-L29 -> 0.40121784
B30: Grooming | C30: organic_volume_growth | D30: PCENDC96 | E30: 2026-04-24 | F30: 2024-03-31 | G30: ='Quarterly market'!G48 -> 1.372616 | H30: ='PG history'!G63 -> 2 | I30: =G30*G30 -> 1.8840747 | J30: =H30*H30 -> 4 | K30: =G30*H30 -> 2.745232 | L30: ='Model tests'!H7+'Model tests'!G7*G30 -> -0.22200682 | M30: =H30-L30 -> 2.2220068 | N30: =AVERAGE(H22:H29)+((SUM(K22:K29)-SUM(G22:G29)*SUM(H22:H29)/COUNT(G22:G29))/(SUM(I22:I29)-SUM(G22:G29)^2/COUNT(G22:G29)))*(G30-AVERAGE(G22:G29)) -> -0.44300324 | O30: =AVERAGE(H26:H29) -> -0.75 | P30: =(H30-N30)^2 -> 5.9682649 | Q30: =(H30-O30)^2 -> 7.5625
B31: Grooming | C31: organic_volume_growth | D31: PCENDC96 | E31: 2026-04-24 | F31: 2024-06-30 | G31: ='Quarterly market'!G49 -> 2.2805944 | H31: ='PG history'!G70 -> 2 | I31: =G31*G31 -> 5.2011107 | J31: =H31*H31 -> 4 | K31: =G31*H31 -> 4.5611888 | L31: ='Model tests'!H7+'Model tests'!G7*G31 -> 0.65178351 | M31: =H31-L31 -> 1.3482165 | N31: =AVERAGE(H22:H30)+((SUM(K22:K30)-SUM(G22:G30)*SUM(H22:H30)/COUNT(G22:G30))/(SUM(I22:I30)-SUM(G22:G30)^2/COUNT(G22:G30)))*(G31-AVERAGE(G22:G30)) -> 0.87794948 | O31: =AVERAGE(H27:H30) -> 0 | P31: =(H31-N31)^2 -> 1.2589974 | Q31: =(H31-O31)^2 -> 4
B32: Grooming | C32: organic_volume_growth | D32: PCENDC96 | E32: 2026-04-24 | F32: 2024-09-30 | G32: ='Quarterly market'!G50 -> 2.6501995 | H32: ='PG history'!G77 -> 5 | I32: =G32*G32 -> 7.0235576 | J32: =H32*H32 -> 25 | K32: =G32*H32 -> 13.250998 | L32: ='Model tests'!H7+'Model tests'!G7*G32 -> 1.0074719 | M32: =H32-L32 -> 3.9925281 | N32: =AVERAGE(H22:H31)+((SUM(K22:K31)-SUM(G22:G31)*SUM(H22:H31)/COUNT(G22:G31))/(SUM(I22:I31)-SUM(G22:G31)^2/COUNT(G22:G31)))*(G32-AVERAGE(G22:G31)) -> 1.5203439 | O32: =AVERAGE(H28:H31) -> 0.75 | P32: =(H32-N32)^2 -> 12.108007 | Q32: =(H32-O32)^2 -> 18.0625
B33: Grooming | C33: organic_volume_growth | D33: PCENDC96 | E33: 2026-04-24 | F33: 2024-12-31 | G33: ='Quarterly market'!G51 -> 2.7872397 | H33: ='PG history'!G84 -> 2 | I33: =G33*G33 -> 7.7687052 | J33: =H33*H33 -> 4 | K33: =G33*H33 -> 5.5744794 | L33: ='Model tests'!H7+'Model tests'!G7*G33 -> 1.1393522 | M33: =H33-L33 -> 0.86064784 | N33: =AVERAGE(H22:H32)+((SUM(K22:K32)-SUM(G22:G32)*SUM(H22:H32)/COUNT(G22:G32))/(SUM(I22:I32)-SUM(G22:G32)^2/COUNT(G22:G32)))*(G33-AVERAGE(G22:G32)) -> 2.3952585 | O33: =AVERAGE(H29:H32) -> 2.5 | P33: =(H33-N33)^2 -> 0.15622925 | Q33: =(H33-O33)^2 -> 0.25
B34: Grooming | C34: organic_volume_growth | D34: PCENDC96 | E34: 2026-04-24 | F34: 2025-03-31 | G34: ='Quarterly market'!G52 -> 3.7498513 | H34: ='PG history'!G91 -> 1 | I34: =G34*G34 -> 14.061385 | J34: =H34*H34 -> 1 | K34: =G34*H34 -> 3.7498513 | L34: ='Model tests'!H7+'Model tests'!G7*G34 -> 2.0657186 | M34: =H34-L34 -> -1.0657186 | N34: =AVERAGE(H22:H33)+((SUM(K22:K33)-SUM(G22:G33)*SUM(H22:H33)/COUNT(G22:G33))/(SUM(I22:I33)-SUM(G22:G33)^2/COUNT(G22:G33)))*(G34-AVERAGE(G22:G33)) -> 3.606601 | O34: =AVERAGE(H30:H33) -> 2.75 | P34: =(H34-N34)^2 -> 6.7943689 | Q34: =(H34-O34)^2 -> 3.0625
B35: Grooming | C35: organic_volume_growth | D35: PCENDC96 | E35: 2026-04-24 | F35: 2025-06-30 | G35: ='Quarterly market'!G53 -> 3.2332745 | H35: ='PG history'!G98 -> -1 | I35: =G35*G35 -> 10.454064 | J35: =H35*H35 -> 1 | K35: =G35*H35 -> -3.2332745 | L35: ='Model tests'!H7+'Model tests'!G7*G35 -> 1.5685924 | M35: =H35-L35 -> -2.5685924 | N35: =AVERAGE(H22:H34)+((SUM(K22:K34)-SUM(G22:G34)*SUM(H22:H34)/COUNT(G22:G34))/(SUM(I22:I34)-SUM(G22:G34)^2/COUNT(G22:G34)))*(G35-AVERAGE(G22:G34)) -> 2.3889586 | O35: =AVERAGE(H31:H34) -> 2.5 | P35: =(H35-N35)^2 -> 11.48504 | Q35: =(H35-O35)^2 -> 12.25
B36: Grooming | C36: organic_volume_growth | D36: PCENDC96 | E36: 2026-04-24 | F36: 2025-09-30 | G36: ='Quarterly market'!G54 -> 2.9967231 | H36: ='PG history'!G105 -> 1 | I36: =G36*G36 -> 8.9803493 | J36: =H36*H36 -> 1 | K36: =G36*H36 -> 2.9967231 | L36: ='Model tests'!H7+'Model tests'!G7*G36 -> 1.3409479 | M36: =H36-L36 -> -0.34094788 | N36: =AVERAGE(H22:H35)+((SUM(K22:K35)-SUM(G22:G35)*SUM(H22:H35)/COUNT(G22:G35))/(SUM(I22:I35)-SUM(G22:G35)^2/COUNT(G22:G35)))*(G36-AVERAGE(G22:G35)) -> 1.6375934 | O36: =AVERAGE(H32:H35) -> 1.75 | P36: =(H36-N36)^2 -> 0.40652536 | Q36: =(H36-O36)^2 -> 0.5625
B37: Grooming | C37: organic_volume_growth | D37: PCENDC96 | E37: 2026-04-24 | F37: 2025-12-31 | G37: ='Quarterly market'!G55 -> 2.1478109 | H37: ='PG history'!G112 -> -2 | I37: =G37*G37 -> 4.6130916 | J37: =H37*H37 -> 4 | K37: =G37*H37 -> -4.2956218 | L37: ='Model tests'!H7+'Model tests'!G7*G37 -> 0.5239997 | M37: =H37-L37 -> -2.5239997 | N37: =AVERAGE(H22:H36)+((SUM(K22:K36)-SUM(G22:G36)*SUM(H22:H36)/COUNT(G22:G36))/(SUM(I22:I36)-SUM(G22:G36)^2/COUNT(G22:G36)))*(G37-AVERAGE(G22:G36)) -> 0.71579951 | O37: =AVERAGE(H33:H36) -> 0.75 | P37: =(H37-N37)^2 -> 7.375567 | Q37: =(H37-O37)^2 -> 7.5625
B38: Health Care | C38: organic_volume_growth | D38: PCENDC96 | E38: 2026-04-24 | F38: 2022-03-31 | G38: ='Quarterly market'!G40 -> 3.5989105 | H38: ='PG history'!G8 -> 8 | I38: =G38*G38 -> 12.952157 | J38: =H38*H38 -> 64 | K38: =G38*H38 -> 28.791284 | L38: ='Model tests'!H8+'Model tests'!G8*G38 -> 0.1671365 | M38: =H38-L38 -> 7.8328635
B39: Health Care | C39: organic_volume_growth | D39: PCENDC96 | E39: 2026-04-24 | F39: 2022-06-30 | G39: ='Quarterly market'!G41 -> -0.03796621 | H39: ='PG history'!G15 -> 0 | I39: =G39*G39 -> 0.0014414331 | J39: =H39*H39 -> 0 | K39: =G39*H39 -> 0 | L39: ='Model tests'!H8+'Model tests'!G8*G39 -> -1.120676 | M39: =H39-L39 -> 1.120676
B40: Health Care | C40: organic_volume_growth | D40: PCENDC96 | E40: 2026-04-24 | F40: 2022-09-30 | G40: ='Quarterly market'!G42 -> -0.97428175 | H40: ='PG history'!G22 -> -2 | I40: =G40*G40 -> 0.94922494 | J40: =H40*H40 -> 4 | K40: =G40*H40 -> 1.9485635 | L40: ='Model tests'!H8+'Model tests'!G8*G40 -> -1.452224 | M40: =H40-L40 -> -0.54777604
B41: Health Care | C41: organic_volume_growth | D41: PCENDC96 | E41: 2026-04-24 | F41: 2022-12-31 | G41: ='Quarterly market'!G43 -> -1.7083333 | H41: ='PG history'!G29 -> -1 | I41: =G41*G41 -> 2.9184028 | J41: =H41*H41 -> 1 | K41: =G41*H41 -> 1.7083333 | L41: ='Model tests'!H8+'Model tests'!G8*G41 -> -1.7121505 | M41: =H41-L41 -> 0.71215051
B42: Health Care | C42: organic_volume_growth | D42: PCENDC96 | E42: 2026-04-24 | F42: 2023-03-31 | G42: ='Quarterly market'!G44 -> -0.51383557 | H42: ='PG history'!G36 -> 1 | I42: =G42*G42 -> 0.264027 | J42: =H42*H42 -> 1 | K42: =G42*H42 -> -0.51383557 | L42: ='Model tests'!H8+'Model tests'!G8*G42 -> -1.2891807 | M42: =H42-L42 -> 2.2891807
B43: Health Care | C43: organic_volume_growth | D43: PCENDC96 | E43: 2026-04-24 | F43: 2023-06-30 | G43: ='Quarterly market'!G45 -> -0.38380426 | H43: ='PG history'!G43 -> -3 | I43: =G43*G43 -> 0.14730571 | J43: =H43*H43 -> 9 | K43: =G43*H43 -> 1.1514128 | L43: ='Model tests'!H8+'Model tests'!G8*G43 -> -1.2431368 | M43: =H43-L43 -> -1.7568632
...

Sheet Quarterly market
B2: Monthly to quarterly | Match periods first
B5: Series | C5: Known by | D5: Quarter ended | E5: Quarter level | F5: Prior-year level | G5: Year-on-year % | H5: Months
B6: RSHPCS | C6: 2026-04-24 | D6: 2022-03-31 | E6: =SUM('Monthly market'!E18,'Monthly market'!E19,'Monthly market'!E20) -> 97633 | F6: =SUM('Monthly market'!E6,'Monthly market'!E7,'Monthly market'!E8) -> 91538 | G6: =(E6/F6-1)*100 -> 6.6584369 | H6: 3
B7: RSHPCS | C7: 2026-04-24 | D7: 2022-06-30 | E7: =SUM('Monthly market'!E21,'Monthly market'!E22,'Monthly market'!E23) -> 98706 | F7: =SUM('Monthly market'!E9,'Monthly market'!E10,'Monthly market'!E11) -> 95612 | G7: =(E7/F7-1)*100 -> 3.2359955 | H7: 3
B8: RSHPCS | C8: 2026-04-24 | D8: 2022-09-30 | E8: =SUM('Monthly market'!E24,'Monthly market'!E25,'Monthly market'!E26) -> 100278 | F8: =SUM('Monthly market'!E12,'Monthly market'!E13,'Monthly market'!E14) -> 96837 | G8: =(E8/F8-1)*100 -> 3.5533938 | H8: 3
B9: RSHPCS | C9: 2026-04-24 | D9: 2022-12-31 | E9: =SUM('Monthly market'!E27,'Monthly market'!E28,'Monthly market'!E29) -> 100667 | F9: =SUM('Monthly market'!E15,'Monthly market'!E16,'Monthly market'!E17) -> 96979 | G9: =(E9/F9-1)*100 -> 3.8028852 | H9: 3
B10: RSHPCS | C10: 2026-04-24 | D10: 2023-03-31 | E10: =SUM('Monthly market'!E30,'Monthly market'!E31,'Monthly market'!E32) -> 104880 | F10: =SUM('Monthly market'!E18,'Monthly market'!E19,'Monthly market'!E20) -> 97633 | G10: =(E10/F10-1)*100 -> 7.4226952 | H10: 3
B11: RSHPCS | C11: 2026-04-24 | D11: 2023-06-30 | E11: =SUM('Monthly market'!E33,'Monthly market'!E34,'Monthly market'!E35) -> 106972 | F11: =SUM('Monthly market'!E21,'Monthly market'!E22,'Monthly market'!E23) -> 98706 | G11: =(E11/F11-1)*100 -> 8.3743643 | H11: 3
B12: RSHPCS | C12: 2026-04-24 | D12: 2023-09-30 | E12: =SUM('Monthly market'!E36,'Monthly market'!E37,'Monthly market'!E38) -> 107563 | F12: =SUM('Monthly market'!E24,'Monthly market'!E25,'Monthly market'!E26) -> 100278 | G12: =(E12/F12-1)*100 -> 7.2648038 | H12: 3
B13: RSHPCS | C13: 2026-04-24 | D13: 2023-12-31 | E13: =SUM('Monthly market'!E39,'Monthly market'!E40,'Monthly market'!E41) -> 110658 | F13: =SUM('Monthly market'!E27,'Monthly market'!E28,'Monthly market'!E29) -> 100667 | G13: =(E13/F13-1)*100 -> 9.9248016 | H13: 3
B14: RSHPCS | C14: 2026-04-24 | D14: 2024-03-31 | E14: =SUM('Monthly market'!E42,'Monthly market'!E43,'Monthly market'!E44) -> 107216 | F14: =SUM('Monthly market'!E30,'Monthly market'!E31,'Monthly market'!E32) -> 104880 | G14: =(E14/F14-1)*100 -> 2.2273074 | H14: 3
B15: RSHPCS | C15: 2026-04-24 | D15: 2024-06-30 | E15: =SUM('Monthly market'!E45,'Monthly market'!E46,'Monthly market'!E47) -> 107827 | F15: =SUM('Monthly market'!E33,'Monthly market'!E34,'Monthly market'!E35) -> 106972 | G15: =(E15/F15-1)*100 -> 0.79927458 | H15: 3
B16: RSHPCS | C16: 2026-04-24 | D16: 2024-09-30 | E16: =SUM('Monthly market'!E48,'Monthly market'!E49,'Monthly market'!E50) -> 113573 | F16: =SUM('Monthly market'!E36,'Monthly market'!E37,'Monthly market'!E38) -> 107563 | G16: =(E16/F16-1)*100 -> 5.5874232 | H16: 3
B17: RSHPCS | C17: 2026-04-24 | D17: 2024-12-31 | E17: =SUM('Monthly market'!E51,'Monthly market'!E52,'Monthly market'!E53) -> 114112 | F17: =SUM('Monthly market'!E39,'Monthly market'!E40,'Monthly market'!E41) -> 110658 | G17: =(E17/F17-1)*100 -> 3.1213288 | H17: 3
B18: RSHPCS | C18: 2026-04-24 | D18: 2025-03-31 | E18: =SUM('Monthly market'!E54,'Monthly market'!E55,'Monthly market'!E56) -> 115895 | F18: =SUM('Monthly market'!E42,'Monthly market'!E43,'Monthly market'!E44) -> 107216 | G18: =(E18/F18-1)*100 -> 8.0948739 | H18: 3
B19: RSHPCS | C19: 2026-04-24 | D19: 2025-06-30 | E19: =SUM('Monthly market'!E57,'Monthly market'!E58,'Monthly market'!E59) -> 117502 | F19: =SUM('Monthly market'!E45,'Monthly market'!E46,'Monthly market'!E47) -> 107827 | G19: =(E19/F19-1)*100 -> 8.9727063 | H19: 3
B20: RSHPCS | C20: 2026-04-24 | D20: 2025-09-30 | E20: =SUM('Monthly market'!E60,'Monthly market'!E61,'Monthly market'!E62) -> 120937 | F20: =SUM('Monthly market'!E48,'Monthly market'!E49,'Monthly market'!E50) -> 113573 | G20: =(E20/F20-1)*100 -> 6.4839354 | H20: 3
B21: RSHPCS | C21: 2026-04-24 | D21: 2025-12-31 | E21: =SUM('Monthly market'!E63,'Monthly market'!E64,'Monthly market'!E65) -> 120797 | F21: =SUM('Monthly market'!E51,'Monthly market'!E52,'Monthly market'!E53) -> 114112 | G21: =(E21/F21-1)*100 -> 5.8582796 | H21: 3
B22: RSHPCS | C22: 2026-04-24 | D22: 2026-03-31 | E22: =SUM('Monthly market'!E66,'Monthly market'!E67,'Monthly market'!E68) -> 118465 | F22: =SUM('Monthly market'!E54,'Monthly market'!E55,'Monthly market'!E56) -> 115895 | G22: =(E22/F22-1)*100 -> 2.2175245 | H22: 3
B23: RSHPCS | C23: 2026-05-15 | D23: 2022-03-31 | E23: =SUM('Monthly market'!E81,'Monthly market'!E82,'Monthly market'!E83) -> 97633 | F23: =SUM('Monthly market'!E69,'Monthly market'!E70,'Monthly market'!E71) -> 91538 | G23: =(E23/F23-1)*100 -> 6.6584369 | H23: 3
B24: RSHPCS | C24: 2026-05-15 | D24: 2022-06-30 | E24: =SUM('Monthly market'!E84,'Monthly market'!E85,'Monthly market'!E86) -> 98706 | F24: =SUM('Monthly market'!E72,'Monthly market'!E73,'Monthly market'!E74) -> 95612 | G24: =(E24/F24-1)*100 -> 3.2359955 | H24: 3
B25: RSHPCS | C25: 2026-05-15 | D25: 2022-09-30 | E25: =SUM('Monthly market'!E87,'Monthly market'!E88,'Monthly market'!E89) -> 100278 | F25: =SUM('Monthly market'!E75,'Monthly market'!E76,'Monthly market'!E77) -> 96837 | G25: =(E25/F25-1)*100 -> 3.5533938 | H25: 3
B26: RSHPCS | C26: 2026-05-15 | D26: 2022-12-31 | E26: =SUM('Monthly market'!E90,'Monthly market'!E91,'Monthly market'!E92) -> 100667 | F26: =SUM('Monthly market'!E78,'Monthly market'!E79,'Monthly market'!E80) -> 96979 | G26: =(E26/F26-1)*100 -> 3.8028852 | H26: 3
B27: RSHPCS | C27: 2026-05-15 | D27: 2023-03-31 | E27: =SUM('Monthly market'!E93,'Monthly market'!E94,'Monthly market'!E95) -> 104880 | F27: =SUM('Monthly market'!E81,'Monthly market'!E82,'Monthly market'!E83) -> 97633 | G27: =(E27/F27-1)*100 -> 7.4226952 | H27: 3
B28: RSHPCS | C28: 2026-05-15 | D28: 2023-06-30 | E28: =SUM('Monthly market'!E96,'Monthly market'!E97,'Monthly market'!E98) -> 106972 | F28: =SUM('Monthly market'!E84,'Monthly market'!E85,'Monthly market'!E86) -> 98706 | G28: =(E28/F28-1)*100 -> 8.3743643 | H28: 3
B29: RSHPCS | C29: 2026-05-15 | D29: 2023-09-30 | E29: =SUM('Monthly market'!E99,'Monthly market'!E100,'Monthly market'!E101) -> 107563 | F29: =SUM('Monthly market'!E87,'Monthly market'!E88,'Monthly market'!E89) -> 100278 | G29: =(E29/F29-1)*100 -> 7.2648038 | H29: 3
B30: RSHPCS | C30: 2026-05-15 | D30: 2023-12-31 | E30: =SUM('Monthly market'!E102,'Monthly market'!E103,'Monthly market'!E104) -> 110658 | F30: =SUM('Monthly market'!E90,'Monthly market'!E91,'Monthly market'!E92) -> 100667 | G30: =(E30/F30-1)*100 -> 9.9248016 | H30: 3
B31: RSHPCS | C31: 2026-05-15 | D31: 2024-03-31 | E31: =SUM('Monthly market'!E105,'Monthly market'!E106,'Monthly market'!E107) -> 107216 | F31: =SUM('Monthly market'!E93,'Monthly market'!E94,'Monthly market'!E95) -> 104880 | G31: =(E31/F31-1)*100 -> 2.2273074 | H31: 3
B32: RSHPCS | C32: 2026-05-15 | D32: 2024-06-30 | E32: =SUM('Monthly market'!E108,'Monthly market'!E109,'Monthly market'!E110) -> 107827 | F32: =SUM('Monthly market'!E96,'Monthly market'!E97,'Monthly market'!E98) -> 106972 | G32: =(E32/F32-1)*100 -> 0.79927458 | H32: 3
B33: RSHPCS | C33: 2026-05-15 | D33: 2024-09-30 | E33: =SUM('Monthly market'!E111,'Monthly market'!E112,'Monthly market'!E113) -> 113573 | F33: =SUM('Monthly market'!E99,'Monthly market'!E100,'Monthly market'!E101) -> 107563 | G33: =(E33/F33-1)*100 -> 5.5874232 | H33: 3
B34: RSHPCS | C34: 2026-05-15 | D34: 2024-12-31 | E34: =SUM('Monthly market'!E114,'Monthly market'!E115,'Monthly market'!E116) -> 114112 | F34: =SUM('Monthly market'!E102,'Monthly market'!E103,'Monthly market'!E104) -> 110658 | G34: =(E34/F34-1)*100 -> 3.1213288 | H34: 3
B35: RSHPCS | C35: 2026-05-15 | D35: 2025-03-31 | E35: =SUM('Monthly market'!E117,'Monthly market'!E118,'Monthly market'!E119) -> 115816 | F35: =SUM('Monthly market'!E105,'Monthly market'!E106,'Monthly market'!E107) -> 107216 | G35: =(E35/F35-1)*100 -> 8.0211909 | H35: 3
B36: RSHPCS | C36: 2026-05-15 | D36: 2025-06-30 | E36: =SUM('Monthly market'!E120,'Monthly market'!E121,'Monthly market'!E122) -> 117819 | F36: =SUM('Monthly market'!E108,'Monthly market'!E109,'Monthly market'!E110) -> 107827 | G36: =(E36/F36-1)*100 -> 9.2666957 | H36: 3
B37: RSHPCS | C37: 2026-05-15 | D37: 2025-09-30 | E37: =SUM('Monthly market'!E123,'Monthly market'!E124,'Monthly market'!E125) -> 120937 | F37: =SUM('Monthly market'!E111,'Monthly market'!E112,'Monthly market'!E113) -> 113573 | G37: =(E37/F37-1)*100 -> 6.4839354 | H37: 3
B38: RSHPCS | C38: 2026-05-15 | D38: 2025-12-31 | E38: =SUM('Monthly market'!E126,'Monthly market'!E127,'Monthly market'!E128) -> 120797 | F38: =SUM('Monthly market'!E114,'Monthly market'!E115,'Monthly market'!E116) -> 114112 | G38: =(E38/F38-1)*100 -> 5.8582796 | H38: 3
B39: RSHPCS | C39: 2026-05-15 | D39: 2026-03-31 | E39: =SUM('Monthly market'!E129,'Monthly market'!E130,'Monthly market'!E131) -> 118700 | F39: =SUM('Monthly market'!E117,'Monthly market'!E118,'Monthly market'!E119) -> 115816 | G39: =(E39/F39-1)*100 -> 2.4901568 | H39: 3
B40: PCENDC96 | C40: 2026-04-24 | D40: 2022-03-31 | E40: =AVERAGE('Monthly market'!E145,'Monthly market'!E146,'Monthly market'!E147) -> 3334.4 | F40: =AVERAGE('Monthly market'!E133,'Monthly market'!E134,'Monthly market'!E135) -> 3218.5667 | G40: =(E40/F40-1)*100 -> 3.5989105 | H40: 3
B41: PCENDC96 | C41: 2026-04-24 | D41: 2022-06-30 | E41: =AVERAGE('Monthly market'!E148,'Monthly market'!E149,'Monthly market'!E150) -> 3335.0333 | F41: =AVERAGE('Monthly market'!E136,'Monthly market'!E137,'Monthly market'!E138) -> 3336.3 | G41: =(E41/F41-1)*100 -> -0.03796621 | H41: 3
B42: PCENDC96 | C42: 2026-04-24 | D42: 2022-09-30 | E42: =AVERAGE('Monthly market'!E151,'Monthly market'!E152,'Monthly market'!E153) -> 3310.0667 | F42: =AVERAGE('Monthly market'!E139,'Monthly market'!E140,'Monthly market'!E141) -> 3342.6333 | G42: =(E42/F42-1)*100 -> -0.97428175 | H42: 3
B43: PCENDC96 | C43: 2026-04-24 | D43: 2022-12-31 | E43: =AVERAGE('Monthly market'!E154,'Monthly market'!E155,'Monthly market'!E156) -> 3302.6 | F43: =AVERAGE('Monthly market'!E142,'Monthly market'!E143,'Monthly market'!E144) -> 3360 | G43: =(E43/F43-1)*100 -> -1.7083333 | H43: 3
...

Sheet PG history
B2: P&G | Quarterly facts
B3: January 2022–March 2026. Sales in USD millions; growth and contributions in %.
B5: Quarter ended | C5: Business segment | D5: Net sales | E5: Sales growth | F5: Organic growth | G5: Organic volume | H5: Pricing | I5: Mix | J5: FX | K5: Published
B6: 2022-03-31 | C6: Beauty | D6: 3389 | E6: 2 | F6: 3 | G6: -1 | H6: 4 | I6: 0 | J6: -2 | K6: 2022-04-20
B7: 2022-03-31 | C7: Grooming | D7: 1481 | E7: 3 | F7: 8 | G7: 1 | H7: 6 | I7: 1 | J7: -5 | K7: 2022-04-20
B8: 2022-03-31 | C8: Health Care | D8: 2662 | E8: 13 | F8: 16 | G8: 8 | H8: 3 | I8: 5 | J8: -3 | K8: 2022-04-20
B9: 2022-03-31 | C9: Fabric & Home Care | D9: 6699 | E9: 7 | F9: 10 | G9: 5 | H9: 5 | I9: 1 | J9: -3 | K9: 2022-04-20
B10: 2022-03-31 | C10: Baby, Feminine & Family Care | D10: 4935 | E10: 7 | F10: 10 | G10: 2 | H10: 5 | I10: 2 | J10: -3 | K10: 2022-04-20
B11: 2022-03-31 | C11: Corporate | D11: 215 | K11: 2022-04-20
B12: 2022-03-31 | C12: Total Company | D12: 19381 | E12: 7 | F12: 10 | G12: 3 | H12: 5 | I12: 2 | J12: -3 | K12: 2022-04-20
B13: 2022-06-30 | C13: Beauty | D13: 3461 | E13: -1 | F13: 0 | G13: -2 | H13: 6 | I13: -4 | J13: -3 | K13: 2022-07-29
B14: 2022-06-30 | C14: Grooming | D14: 1608 | E14: -3 | F14: 3 | G14: -2 | H14: 6 | I14: -1 | J14: -6 | K14: 2022-07-29
B15: 2022-06-30 | C15: Health Care | D15: 2510 | E15: 5 | F15: 9 | G15: 0 | H15: 5 | I15: 4 | J15: -4 | K15: 2022-07-29
B16: 2022-06-30 | C16: Fabric & Home Care | D16: 6876 | E16: 4 | F16: 9 | G16: -1 | H16: 10 | I16: 0 | J16: -5 | K16: 2022-07-29
B17: 2022-06-30 | C17: Baby, Feminine & Family Care | D17: 4821 | E17: 3 | F17: 7 | G17: 0 | H17: 6 | I17: 1 | J17: -3 | K17: 2022-07-29
B18: 2022-06-30 | C18: Corporate | D18: 239 | K18: 2022-07-29
B19: 2022-06-30 | C19: Total Company | D19: 19515 | E19: 3 | F19: 7 | G19: -1 | H19: 8 | I19: 0 | J19: -4 | K19: 2022-07-29
B20: 2022-09-30 | C20: Beauty | D20: 3961 | E20: 0 | F20: 4 | G20: -1 | H20: 7 | I20: -2 | J20: -6 | K20: 2022-10-19
B21: 2022-09-30 | C21: Grooming | D21: 1625 | E21: -4 | F21: 5 | G21: 1 | H21: 8 | I21: -4 | J21: -8 | K21: 2022-10-19
B22: 2022-09-30 | C22: Health Care | D22: 2757 | E22: 3 | F22: 8 | G22: -2 | H22: 6 | I22: 4 | J22: -5 | K22: 2022-10-19
B23: 2022-09-30 | C23: Fabric & Home Care | D23: 7082 | E23: 1 | F23: 8 | G23: -4 | H23: 11 | I23: 1 | J23: -6 | K23: 2022-10-19
B24: 2022-09-30 | C24: Baby, Feminine & Family Care | D24: 4934 | E24: 1 | F24: 6 | G24: -3 | H24: 8 | I24: 1 | J24: -5 | K24: 2022-10-19
B25: 2022-09-30 | C25: Corporate | D25: 253 | K25: 2022-10-19
B26: 2022-09-30 | C26: Total Company | D26: 20612 | E26: 1 | F26: 7 | G26: -3 | H26: 9 | I26: 1 | J26: -6 | K26: 2022-10-19
B27: 2022-12-31 | C27: Beauty | D27: 3807 | E27: -3 | F27: 3 | G27: -4 | H27: 9 | I27: -2 | J27: -8 | K27: 2023-01-19
B28: 2022-12-31 | C28: Grooming | D28: 1643 | E28: -9 | F28: 0 | G28: -8 | H28: 11 | I28: -3 | J28: -9 | K28: 2023-01-19
B29: 2022-12-31 | C29: Health Care | D29: 3051 | E29: 2 | F29: 8 | G29: -1 | H29: 5 | I29: 4 | J29: -6 | K29: 2023-01-19
B30: 2022-12-31 | C30: Fabric & Home Care | D30: 7032 | E30: 1 | F30: 8 | G30: -7 | H30: 13 | I30: 2 | J30: -7 | K30: 2023-01-19
B31: 2022-12-31 | C31: Baby, Feminine & Family Care | D31: 5065 | E31: -1 | F31: 4 | G31: -6 | H31: 8 | I31: 2 | J31: -5 | K31: 2023-01-19
B32: 2022-12-31 | C32: Corporate | D32: 175 | K32: 2023-01-19
B33: 2022-12-31 | C33: Total Company | D33: 20773 | E33: -1 | F33: 5 | G33: -6 | H33: 10 | I33: 1 | J33: -6 | K33: 2023-01-19
B34: 2023-03-31 | C34: Beauty | D34: 3494 | E34: 3 | F34: 7 | G34: 0 | H34: 8 | I34: -1 | J34: -5 | K34: 2023-04-21
B35: 2023-03-31 | C35: Grooming | D35: 1495 | E35: 1 | F35: 7 | G35: -1 | H35: 10 | I35: -2 | J35: -6 | K35: 2023-04-21
B36: 2023-03-31 | C36: Health Care | D36: 2828 | E36: 6 | F36: 9 | G36: 1 | H36: 6 | I36: 3 | J36: -3 | K36: 2023-04-21
B37: 2023-03-31 | C37: Fabric & Home Care | D37: 7016 | E37: 5 | F37: 9 | G37: -5 | H37: 13 | I37: 1 | J37: -4 | K37: 2023-04-21
B38: 2023-03-31 | C38: Baby, Feminine & Family Care | D38: 5062 | E38: 3 | F38: 6 | G38: -4 | H38: 8 | I38: 2 | J38: -3 | K38: 2023-04-21
B39: 2023-03-31 | C39: Corporate | D39: 173 | K39: 2023-04-21
B40: 2023-03-31 | C40: Total Company | D40: 20068 | E40: 4 | F40: 7 | G40: -3 | H40: 10 | I40: 1 | J40: -4 | K40: 2023-04-21
B41: 2023-06-30 | C41: Beauty | D41: 3746 | E41: 8 | F41: 11 | G41: -1 | H41: 8 | I41: 4 | J41: -4 | K41: 2023-07-28
B42: 2023-06-30 | C42: Grooming | D42: 1656 | E42: 3 | F42: 8 | G42: -1 | H42: 9 | I42: 0 | J42: -5 | K42: 2023-07-28
...

Sheet Monthly market
B2: Monthly market | Date-frozen inputs
B5: Series | C5: Known by | D5: Month | E5: Value | F5: Units | G5: Source
B6: RSHPCS | C6: 2026-04-24 | D6: 2021-01-01 | E6: 29812 | F6: USD million, monthly flow, seasonally adjusted | G6: https://alfred.stlouisfed.org/graph/alfredgraph.csv?id=RSHPCS&cosd=2021-01-01&coed=2026-04-01&vintage_date=2026-04-24
B7: RSHPCS | C7: 2026-04-24 | D7: 2021-02-01 | E7: 29636 | F7: USD million, monthly flow, seasonally adjusted | G7: https://alfred.stlouisfed.org/graph/alfredgraph.csv?id=RSHPCS&cosd=2021-01-01&coed=2026-04-01&vintage_date=2026-04-24
B8: RSHPCS | C8: 2026-04-24 | D8: 2021-03-01 | E8: 32090 | F8: USD million, monthly flow, seasonally adjusted | G8: https://alfred.stlouisfed.org/graph/alfredgraph.csv?id=RSHPCS&cosd=2021-01-01&coed=2026-04-01&vintage_date=2026-04-24
B9: RSHPCS | C9: 2026-04-24 | D9: 2021-04-01 | E9: 31957 | F9: USD million, monthly flow, seasonally adjusted | G9: https://alfred.stlouisfed.org/graph/alfredgraph.csv?id=RSHPCS&cosd=2021-01-01&coed=2026-04-01&vintage_date=2026-04-24
B10: RSHPCS | C10: 2026-04-24 | D10: 2021-05-01 | E10: 31321 | F10: USD million, monthly flow, seasonally adjusted | G10: https://alfred.stlouisfed.org/graph/alfredgraph.csv?id=RSHPCS&cosd=2021-01-01&coed=2026-04-01&vintage_date=2026-04-24
B11: RSHPCS | C11: 2026-04-24 | D11: 2021-06-01 | E11: 32334 | F11: USD million, monthly flow, seasonally adjusted | G11: https://alfred.stlouisfed.org/graph/alfredgraph.csv?id=RSHPCS&cosd=2021-01-01&coed=2026-04-01&vintage_date=2026-04-24
B12: RSHPCS | C12: 2026-04-24 | D12: 2021-07-01 | E12: 32225 | F12: USD million, monthly flow, seasonally adjusted | G12: https://alfred.stlouisfed.org/graph/alfredgraph.csv?id=RSHPCS&cosd=2021-01-01&coed=2026-04-01&vintage_date=2026-04-24
B13: RSHPCS | C13: 2026-04-24 | D13: 2021-08-01 | E13: 32429 | F13: USD million, monthly flow, seasonally adjusted | G13: https://alfred.stlouisfed.org/graph/alfredgraph.csv?id=RSHPCS&cosd=2021-01-01&coed=2026-04-01&vintage_date=2026-04-24
B14: RSHPCS | C14: 2026-04-24 | D14: 2021-09-01 | E14: 32183 | F14: USD million, monthly flow, seasonally adjusted | G14: https://alfred.stlouisfed.org/graph/alfredgraph.csv?id=RSHPCS&cosd=2021-01-01&coed=2026-04-01&vintage_date=2026-04-24
B15: RSHPCS | C15: 2026-04-24 | D15: 2021-10-01 | E15: 32099 | F15: USD million, monthly flow, seasonally adjusted | G15: https://alfred.stlouisfed.org/graph/alfredgraph.csv?id=RSHPCS&cosd=2021-01-01&coed=2026-04-01&vintage_date=2026-04-24
B16: RSHPCS | C16: 2026-04-24 | D16: 2021-11-01 | E16: 32490 | F16: USD million, monthly flow, seasonally adjusted | G16: https://alfred.stlouisfed.org/graph/alfredgraph.csv?id=RSHPCS&cosd=2021-01-01&coed=2026-04-01&vintage_date=2026-04-24
B17: RSHPCS | C17: 2026-04-24 | D17: 2021-12-01 | E17: 32390 | F17: USD million, monthly flow, seasonally adjusted | G17: https://alfred.stlouisfed.org/graph/alfredgraph.csv?id=RSHPCS&cosd=2021-01-01&coed=2026-04-01&vintage_date=2026-04-24
... B382: CUUR0000SEGB | C382: 2026-05-15 | D382: 2026-04-01 | E382: 184.895 | F382: Index 1982-84=100, not seasonally adjusted | G382: https://alfred.stlouisfed.org/graph/alfredgraph.csv?id=CUUR0000SEGB&cosd=2021-01-01&coed=2026-04-01&vintage_date=2026-05-15

Sheet Product prices
B2: Product prices | Research only
B3: Current-vintage BLS history. Not used in April/May forecast calculations.
B5: Series | C5: Product group | D5: Month | E5: Price index | F5: Vintage status
B6: CUUR0000SEGB01 | C6: Hair, dental, shaving and miscellaneous personal care products | D6: 2021-01-01 | E6: 103.209 | F6: Retrieved 2026-10-05; historical vintage not verified
B7: CUUR0000SEGB01 | C7: Hair, dental, shaving and miscellaneous personal care products | D7: 2021-02-01 | E7: 103.459 | F7: Retrieved 2026-10-05; historical vintage not verified
B8: CUUR0000SEGB01 | C8: Hair, dental, shaving and miscellaneous personal care products | D8: 2021-03-01 | E8: 103.394 | F8: Retrieved 2026-10-05; historical vintage not verified
B9: CUUR0000SEGB01 | C9: Hair, dental, shaving and miscellaneous personal care products | D9: 2021-04-01 | E9: 103.675 | F9: Retrieved 2026-10-05; historical vintage not verified
B10: CUUR0000SEGB01 | C10: Hair, dental, shaving and miscellaneous personal care products | D10: 2021-05-01 | E10: 103.926 | F10: Retrieved 2026-10-05; historical vintage not verified
B11: CUUR0000SEGB01 | C11: Hair, dental, shaving and miscellaneous personal care products | D11: 2021-06-01 | E11: 103.538 | F11: Retrieved 2026-10-05; historical vintage not verified
B12: CUUR0000SEGB01 | C12: Hair, dental, shaving and miscellaneous personal care products | D12: 2021-07-01 | E12: 104.221 | F12: Retrieved 2026-10-05; historical vintage not verified
B13: CUUR0000SEGB01 | C13: Hair, dental, shaving and miscellaneous personal care products | D13: 2021-08-01 | E13: 104.098 | F13: Retrieved 2026-10-05; historical vintage not verified
B14: CUUR0000SEGB01 | C14: Hair, dental, shaving and miscellaneous personal care products | D14: 2021-09-01 | E14: 103.769 | F14: Retrieved 2026-10-05; historical vintage not verified
B15: CUUR0000SEGB01 | C15: Hair, dental, shaving and miscellaneous personal care products | D15: 2021-10-01 | E15: 104.304 | F15: Retrieved 2026-10-05; historical vintage not verified
B16: CUUR0000SEGB01 | C16: Hair, dental, shaving and miscellaneous personal care products | D16: 2021-11-01 | E16: 104.136 | F16: Retrieved 2026-10-05; historical vintage not verified
B17: CUUR0000SEGB01 | C17: Hair, dental, shaving and miscellaneous personal care products | D17: 2021-12-01 | E17: 104.129 | F17: Retrieved 2026-10-05; historical vintage not verified
... B62: CUUR0000SEGB01 | C62: Hair, dental, shaving and miscellaneous personal care products | D62: 2025-09-01 | E62: 124.066 | F62: Retrieved 2026-10-05; historical vintage not verified
B63: CUUR0000SEGB01 | C63: Hair, dental, shaving and miscellaneous personal care products | D63: 2025-10-01 | F63: Retrieved 2026-10-05; historical vintage not verified
B64: CUUR0000SEGB01 | C64: Hair, dental, shaving and miscellaneous personal care products | D64: 2025-11-01 | E64: 124.059 | F64: Retrieved 2026-10-05; historical vintage not verified
B65: CUUR0000SEGB01 | C65: Hair, dental, shaving and miscellaneous personal care products | D65: 2025-12-01 | E65: 124.018 | F65: Retrieved 2026-10-05; historical vintage not verified
