Workbook

Sheet Review
B2: P&G release-aware backtest
B3: Eight test quarters: April-June 2024 through January-March 2026. Errors in percentage points.
B5: Business segment | C5: Measure | D5: Market RMSE | E5: Four-quarter mean | F5: Last actual | G5: Test quarters
B6: =Scorecard!B22 -> Beauty | C6: Volume growth | D6: =Scorecard!G22 -> 2.4262494 | E6: =Scorecard!H22 -> 1.7410485 | F6: =Scorecard!I22 -> 1.4142136 | G6: =Scorecard!F22 -> 8
B7: =Scorecard!B41 -> Grooming | C7: Volume growth | D7: =Scorecard!G41 -> 2.4544843 | E7: =Scorecard!H41 -> 2.4701341 | F7: =Scorecard!I41 -> 2.1213203 | G7: =Scorecard!F41 -> 8
B8: =Scorecard!B60 -> Health Care | C8: Volume growth | D8: =Scorecard!G60 -> 1.8544294 | E8: =Scorecard!H60 -> 1.5411035 | F8: =Scorecard!I60 -> 2.0615528 | G8: =Scorecard!F60 -> 8
B9: =Scorecard!B79 -> Fabric & Home Care | C9: Volume growth | D9: =Scorecard!G79 -> 2.5796899 | E9: =Scorecard!H79 -> 1.8853879 | F9: =Scorecard!I79 -> 1.767767 | G9: =Scorecard!F79 -> 8
B10: =Scorecard!B98 -> Baby, Feminine & Family Care | C10: Volume growth | D10: =Scorecard!G98 -> 3.0408744 | E10: =Scorecard!H98 -> 3.3830922 | F10: =Scorecard!I98 -> 4.4440972 | G10: =Scorecard!F98 -> 8
B11: =Scorecard!B117 -> Beauty | C11: Pricing contribution | D11: =Scorecard!G117 -> 1.2373816 | E11: =Scorecard!H117 -> 1.7207375 | F11: =Scorecard!I117 -> 1.2747549 | G11: =Scorecard!F117 -> 8
B12: =Scorecard!B136 -> Grooming | C12: Pricing contribution | D12: =Scorecard!G136 -> 2.0552154 | E12: =Scorecard!H136 -> 3.4437443 | F12: =Scorecard!I136 -> 2.5248762 | G12: =Scorecard!F136 -> 8
B13: =Scorecard!B155 -> Beauty | C13: Organic sales growth | D13: =Scorecard!G155 -> 3.0969202 | E13: =Scorecard!H155 -> 3.0220544 | F13: =Scorecard!I155 -> 3.1622777 | G13: =Scorecard!F155 -> 8
B14: =Scorecard!B174 -> Health Care | C14: Organic sales growth | D14: =Scorecard!G174 -> 3.8101096 | E14: =Scorecard!H174 -> 1.118034 | F14: =Scorecard!I174 -> 1.4142136 | G14: =Scorecard!F174 -> 8
B17: Grooming pricing remains a candidate; Beauty barely beats the last-actual rule.
B18: No model is approved for automatic scenario changes from eight test quarters.
B21: Pricing model | C21: Market-only RMSE | D21: 50/50 blend RMSE | E21: Conclusion
B22: Beauty | C22: =Scorecard!G117 -> 1.2373816 | D22: =Scorecard!G119 -> 1.3644921 | E22: =IF(D22<C22,"Blend improved","Blend worsened") -> Blend worsened
B23: Grooming | C23: =Scorecard!G136 -> 2.0552154 | D23: =Scorecard!G138 -> 2.683222 | E23: =IF(D23<C23,"Blend improved","Blend worsened") -> Blend worsened
B26: 50/50 blending is tested, not assumed to fix weak data. No regional weights were invented.
B27: Frozen inputs preserve historical availability. A rerun is required to add new releases.
B28: This is retrospective model development, not an untouched prospective test.

Sheet Quarter example
B2: Grooming pricing: January-March 2026
B3: Updates can worsen a forecast. Actual pricing contribution: 3pp, published 24 April.
B5: Forecast date | C5: Observed months | D5: Last actual rule | E5: Market model | F5: Actual (later) | G5: Model error pp | J5: Date label
B6: ='Forecast log'!F446 -> 46023 | C6: ='Forecast log'!G446 -> 0 | D6: ='Forecast log'!I446 -> 4 | E6: ='Forecast log'!N446 -> 3.8752792 | F6: ='PG facts'!E119 -> 3 | G6: =E6-F6 -> 0.8752792 | J6: =TEXT(B6,"dd-mmm") -> 01-Jan
B7: ='Forecast log'!F447 -> 46035 | C7: ='Forecast log'!G447 -> 0 | D7: ='Forecast log'!I447 -> 4 | E7: ='Forecast log'!N447 -> 4.0143577 | F7: ='PG facts'!E119 -> 3 | G7: =E7-F7 -> 1.0143577 | J7: =TEXT(B7,"dd-mmm") -> 13-Jan
B8: ='Forecast log'!F448 -> 46045 | C8: ='Forecast log'!G448 -> 0 | D8: ='Forecast log'!I448 -> 2 | E8: ='Forecast log'!N448 -> 4.0143577 | F8: ='PG facts'!E119 -> 3 | G8: =E8-F8 -> 1.0143577 | J8: =TEXT(B8,"dd-mmm") -> 23-Jan
B9: ='Forecast log'!F449 -> 46066 | C9: ='Forecast log'!G449 -> 1 | D9: ='Forecast log'!I449 -> 2 | E9: ='Forecast log'!N449 -> 4.3390568 | F9: ='PG facts'!E119 -> 3 | G9: =E9-F9 -> 1.3390568 | J9: =TEXT(B9,"dd-mmm") -> 13-Feb
B10: ='Forecast log'!F450 -> 46092 | C10: ='Forecast log'!G450 -> 2 | D10: ='Forecast log'!I450 -> 2 | E10: ='Forecast log'!N450 -> 4.59835 | F10: ='PG facts'!E119 -> 3 | G10: =E10-F10 -> 1.59835 | J10: =TEXT(B10,"dd-mmm") -> 11-Mar
B11: ='Forecast log'!F451 -> 46122 | C11: ='Forecast log'!G451 -> 3 | D11: ='Forecast log'!I451 -> 2 | E11: ='Forecast log'!N451 -> 4.7910848 | F11: ='PG facts'!E119 -> 3 | G11: =E11-F11 -> 1.7910848 | J11: =TEXT(B11,"dd-mmm") -> 10-Apr
B12: ='Forecast log'!F452 -> 46135 | C12: ='Forecast log'!G452 -> 3 | D12: ='Forecast log'!I452 -> 2 | E12: ='Forecast log'!N452 -> 4.7910848 | F12: ='PG facts'!E119 -> 3 | G12: =E12-F12 -> 1.7910848 | J12: =TEXT(B12,"dd-mmm") -> 23-Apr
B14: Actuals are shown for evaluation only; they do not feed earlier forecasts.

Sheet Scorecard
B2: Model errors on comparable quarters
B5: Segment | C5: Measure | D5: Stage | E5: Method | F5: Quarters | G5: RMSE pp | H5: Mean RMSE pp | I5: Last actual RMSE pp | J5: MAE pp | K5: Bias pp | L5: Wins vs mean
B6: Beauty | C6: organic_volume_growth | D6: Origin | E6: baseline | F6: =COUNTIFS('Scored quarters'!$C$6:$C$1367,B6,'Scored quarters'!$D$6:$D$1367,C6,'Scored quarters'!$F$6:$F$1367,D6,'Scored quarters'!$G$6:$G$1367,E6) -> 8 | G6: =SQRT(SUMIFS('Scored quarters'!$K$6:$K$1367,'Scored quarters'!$C$6:$C$1367,B6,'Scored quarters'!$D$6:$D$1367,C6,'Scored quarters'!$F$6:$F$1367,D6,'Scored quarters'!$G$6:$G$1367,E6)/F6) -> 2.0596571 | H6: =SQRT(SUMIFS('Scored quarters'!$L$6:$L$1367,'Scored quarters'!$C$6:$C$1367,B6,'Scored quarters'!$D$6:$D$1367,C6,'Scored quarters'!$F$6:$F$1367,D6,'Scored quarters'!$G$6:$G$1367,E6)/F6) -> 2.0596571 | I6: =SQRT(SUMIFS('Scored quarters'!$M$6:$M$1367,'Scored quarters'!$C$6:$C$1367,B6,'Scored quarters'!$D$6:$D$1367,C6,'Scored quarters'!$F$6:$F$1367,D6,'Scored quarters'!$G$6:$G$1367,E6)/F6) -> 1.6583124 | J6: =SUMIFS('Scored quarters'!$O$6:$O$1367,'Scored quarters'!$C$6:$C$1367,B6,'Scored quarters'!$D$6:$D$1367,C6,'Scored quarters'!$F$6:$F$1367,D6,'Scored quarters'!$G$6:$G$1367,E6)/F6 -> 1.59375 | K6: =SUMIFS('Scored quarters'!$J$6:$J$1367,'Scored quarters'!$C$6:$C$1367,B6,'Scored quarters'!$D$6:$D$1367,C6,'Scored quarters'!$F$6:$F$1367,D6,'Scored quarters'!$G$6:$G$1367,E6)/F6 -> -1.53125 | L6: =SUMIFS('Scored quarters'!$N$6:$N$1367,'Scored quarters'!$C$6:$C$1367,B6,'Scored quarters'!$D$6:$D$1367,C6,'Scored quarters'!$F$6:$F$1367,D6,'Scored quarters'!$G$6:$G$1367,E6) -> 0
B7: Beauty | C7: organic_volume_growth | D7: Origin | E7: last_actual | F7: =COUNTIFS('Scored quarters'!$C$6:$C$1367,B7,'Scored quarters'!$D$6:$D$1367,C7,'Scored quarters'!$F$6:$F$1367,D7,'Scored quarters'!$G$6:$G$1367,E7) -> 8 | G7: =SQRT(SUMIFS('Scored quarters'!$K$6:$K$1367,'Scored quarters'!$C$6:$C$1367,B7,'Scored quarters'!$D$6:$D$1367,C7,'Scored quarters'!$F$6:$F$1367,D7,'Scored quarters'!$G$6:$G$1367,E7)/F7) -> 1.6583124 | H7: =SQRT(SUMIFS('Scored quarters'!$L$6:$L$1367,'Scored quarters'!$C$6:$C$1367,B7,'Scored quarters'!$D$6:$D$1367,C7,'Scored quarters'!$F$6:$F$1367,D7,'Scored quarters'!$G$6:$G$1367,E7)/F7) -> 2.0596571 | I7: =SQRT(SUMIFS('Scored quarters'!$M$6:$M$1367,'Scored quarters'!$C$6:$C$1367,B7,'Scored quarters'!$D$6:$D$1367,C7,'Scored quarters'!$F$6:$F$1367,D7,'Scored quarters'!$G$6:$G$1367,E7)/F7) -> 1.6583124 | J7: =SUMIFS('Scored quarters'!$O$6:$O$1367,'Scored quarters'!$C$6:$C$1367,B7,'Scored quarters'!$D$6:$D$1367,C7,'Scored quarters'!$F$6:$F$1367,D7,'Scored quarters'!$G$6:$G$1367,E7)/F7 -> 1.5 | K7: =SUMIFS('Scored quarters'!$J$6:$J$1367,'Scored quarters'!$C$6:$C$1367,B7,'Scored quarters'!$D$6:$D$1367,C7,'Scored quarters'!$F$6:$F$1367,D7,'Scored quarters'!$G$6:$G$1367,E7)/F7 -> -1 | L7: =SUMIFS('Scored quarters'!$N$6:$N$1367,'Scored quarters'!$C$6:$C$1367,B7,'Scored quarters'!$D$6:$D$1367,C7,'Scored quarters'!$F$6:$F$1367,D7,'Scored quarters'!$G$6:$G$1367,E7) -> 3
B8: Beauty | C8: organic_volume_growth | D8: Origin | E8: bridge | F8: =COUNTIFS('Scored quarters'!$C$6:$C$1367,B8,'Scored quarters'!$D$6:$D$1367,C8,'Scored quarters'!$F$6:$F$1367,D8,'Scored quarters'!$G$6:$G$1367,E8) -> 8 | G8: =SQRT(SUMIFS('Scored quarters'!$K$6:$K$1367,'Scored quarters'!$C$6:$C$1367,B8,'Scored quarters'!$D$6:$D$1367,C8,'Scored quarters'!$F$6:$F$1367,D8,'Scored quarters'!$G$6:$G$1367,E8)/F8) -> 2.3099248 | H8: =SQRT(SUMIFS('Scored quarters'!$L$6:$L$1367,'Scored quarters'!$C$6:$C$1367,B8,'Scored quarters'!$D$6:$D$1367,C8,'Scored quarters'!$F$6:$F$1367,D8,'Scored quarters'!$G$6:$G$1367,E8)/F8) -> 2.0596571 | I8: =SQRT(SUMIFS('Scored quarters'!$M$6:$M$1367,'Scored quarters'!$C$6:$C$1367,B8,'Scored quarters'!$D$6:$D$1367,C8,'Scored quarters'!$F$6:$F$1367,D8,'Scored quarters'!$G$6:$G$1367,E8)/F8) -> 1.6583124 | J8: =SUMIFS('Scored quarters'!$O$6:$O$1367,'Scored quarters'!$C$6:$C$1367,B8,'Scored quarters'!$D$6:$D$1367,C8,'Scored quarters'!$F$6:$F$1367,D8,'Scored quarters'!$G$6:$G$1367,E8)/F8 -> 1.8495023 | K8: =SUMIFS('Scored quarters'!$J$6:$J$1367,'Scored quarters'!$C$6:$C$1367,B8,'Scored quarters'!$D$6:$D$1367,C8,'Scored quarters'!$F$6:$F$1367,D8,'Scored quarters'!$G$6:$G$1367,E8)/F8 -> -1.8495023 | L8: =SUMIFS('Scored quarters'!$N$6:$N$1367,'Scored quarters'!$C$6:$C$1367,B8,'Scored quarters'!$D$6:$D$1367,C8,'Scored quarters'!$F$6:$F$1367,D8,'Scored quarters'!$G$6:$G$1367,E8) -> 2
B9: Beauty | C9: organic_volume_growth | D9: Origin | E9: blend | F9: =COUNTIFS('Scored quarters'!$C$6:$C$1367,B9,'Scored quarters'!$D$6:$D$1367,C9,'Scored quarters'!$F$6:$F$1367,D9,'Scored quarters'!$G$6:$G$1367,E9) -> 8 | G9: =SQRT(SUMIFS('Scored quarters'!$K$6:$K$1367,'Scored quarters'!$C$6:$C$1367,B9,'Scored quarters'!$D$6:$D$1367,C9,'Scored quarters'!$F$6:$F$1367,D9,'Scored quarters'!$G$6:$G$1367,E9)/F9) -> 2.1801357 | H9: =SQRT(SUMIFS('Scored quarters'!$L$6:$L$1367,'Scored quarters'!$C$6:$C$1367,B9,'Scored quarters'!$D$6:$D$1367,C9,'Scored quarters'!$F$6:$F$1367,D9,'Scored quarters'!$G$6:$G$1367,E9)/F9) -> 2.0596571 | I9: =SQRT(SUMIFS('Scored quarters'!$M$6:$M$1367,'Scored quarters'!$C$6:$C$1367,B9,'Scored quarters'!$D$6:$D$1367,C9,'Scored quarters'!$F$6:$F$1367,D9,'Scored quarters'!$G$6:$G$1367,E9)/F9) -> 1.6583124 | J9: =SUMIFS('Scored quarters'!$O$6:$O$1367,'Scored quarters'!$C$6:$C$1367,B9,'Scored quarters'!$D$6:$D$1367,C9,'Scored quarters'!$F$6:$F$1367,D9,'Scored quarters'!$G$6:$G$1367,E9)/F9 -> 1.7148431 | K9: =SUMIFS('Scored quarters'!$J$6:$J$1367,'Scored quarters'!$C$6:$C$1367,B9,'Scored quarters'!$D$6:$D$1367,C9,'Scored quarters'!$F$6:$F$1367,D9,'Scored quarters'!$G$6:$G$1367,E9)/F9 -> -1.6903762 | L9: =SUMIFS('Scored quarters'!$N$6:$N$1367,'Scored quarters'!$C$6:$C$1367,B9,'Scored quarters'!$D$6:$D$1367,C9,'Scored quarters'!$F$6:$F$1367,D9,'Scored quarters'!$G$6:$G$1367,E9) -> 2
B10: Beauty | C10: organic_volume_growth | D10: First month | E10: baseline | F10: =COUNTIFS('Scored quarters'!$C$6:$C$1367,B10,'Scored quarters'!$D$6:$D$1367,C10,'Scored quarters'!$F$6:$F$1367,D10,'Scored quarters'!$G$6:$G$1367,E10) -> 8 | G10: =SQRT(SUMIFS('Scored quarters'!$K$6:$K$1367,'Scored quarters'!$C$6:$C$1367,B10,'Scored quarters'!$D$6:$D$1367,C10,'Scored quarters'!$F$6:$F$1367,D10,'Scored quarters'!$G$6:$G$1367,E10)/F10) -> 1.7410485 | H10: =SQRT(SUMIFS('Scored quarters'!$L$6:$L$1367,'Scored quarters'!$C$6:$C$1367,B10,'Scored quarters'!$D$6:$D$1367,C10,'Scored quarters'!$F$6:$F$1367,D10,'Scored quarters'!$G$6:$G$1367,E10)/F10) -> 1.7410485 | I10: =SQRT(SUMIFS('Scored quarters'!$M$6:$M$1367,'Scored quarters'!$C$6:$C$1367,B10,'Scored quarters'!$D$6:$D$1367,C10,'Scored quarters'!$F$6:$F$1367,D10,'Scored quarters'!$G$6:$G$1367,E10)/F10) -> 1.4142136 | J10: =SUMIFS('Scored quarters'!$O$6:$O$1367,'Scored quarters'!$C$6:$C$1367,B10,'Scored quarters'!$D$6:$D$1367,C10,'Scored quarters'!$F$6:$F$1367,D10,'Scored quarters'!$G$6:$G$1367,E10)/F10 -> 1.3125 | K10: =SUMIFS('Scored quarters'!$J$6:$J$1367,'Scored quarters'!$C$6:$C$1367,B10,'Scored quarters'!$D$6:$D$1367,C10,'Scored quarters'!$F$6:$F$1367,D10,'Scored quarters'!$G$6:$G$1367,E10)/F10 -> -1.1875 | L10: =SUMIFS('Scored quarters'!$N$6:$N$1367,'Scored quarters'!$C$6:$C$1367,B10,'Scored quarters'!$D$6:$D$1367,C10,'Scored quarters'!$F$6:$F$1367,D10,'Scored quarters'!$G$6:$G$1367,E10) -> 0
B11: Beauty | C11: organic_volume_growth | D11: First month | E11: last_actual | F11: =COUNTIFS('Scored quarters'!$C$6:$C$1367,B11,'Scored quarters'!$D$6:$D$1367,C11,'Scored quarters'!$F$6:$F$1367,D11,'Scored quarters'!$G$6:$G$1367,E11) -> 8 | G11: =SQRT(SUMIFS('Scored quarters'!$K$6:$K$1367,'Scored quarters'!$C$6:$C$1367,B11,'Scored quarters'!$D$6:$D$1367,C11,'Scored quarters'!$F$6:$F$1367,D11,'Scored quarters'!$G$6:$G$1367,E11)/F11) -> 1.4142136 | H11: =SQRT(SUMIFS('Scored quarters'!$L$6:$L$1367,'Scored quarters'!$C$6:$C$1367,B11,'Scored quarters'!$D$6:$D$1367,C11,'Scored quarters'!$F$6:$F$1367,D11,'Scored quarters'!$G$6:$G$1367,E11)/F11) -> 1.7410485 | I11: =SQRT(SUMIFS('Scored quarters'!$M$6:$M$1367,'Scored quarters'!$C$6:$C$1367,B11,'Scored quarters'!$D$6:$D$1367,C11,'Scored quarters'!$F$6:$F$1367,D11,'Scored quarters'!$G$6:$G$1367,E11)/F11) -> 1.4142136 | J11: =SUMIFS('Scored quarters'!$O$6:$O$1367,'Scored quarters'!$C$6:$C$1367,B11,'Scored quarters'!$D$6:$D$1367,C11,'Scored quarters'!$F$6:$F$1367,D11,'Scored quarters'!$G$6:$G$1367,E11)/F11 -> 1 | K11: =SUMIFS('Scored quarters'!$J$6:$J$1367,'Scored quarters'!$C$6:$C$1367,B11,'Scored quarters'!$D$6:$D$1367,C11,'Scored quarters'!$F$6:$F$1367,D11,'Scored quarters'!$G$6:$G$1367,E11)/F11 -> -0.5 | L11: =SUMIFS('Scored quarters'!$N$6:$N$1367,'Scored quarters'!$C$6:$C$1367,B11,'Scored quarters'!$D$6:$D$1367,C11,'Scored quarters'!$F$6:$F$1367,D11,'Scored quarters'!$G$6:$G$1367,E11) -> 6
B12: Beauty | C12: organic_volume_growth | D12: First month | E12: bridge | F12: =COUNTIFS('Scored quarters'!$C$6:$C$1367,B12,'Scored quarters'!$D$6:$D$1367,C12,'Scored quarters'!$F$6:$F$1367,D12,'Scored quarters'!$G$6:$G$1367,E12) -> 8 | G12: =SQRT(SUMIFS('Scored quarters'!$K$6:$K$1367,'Scored quarters'!$C$6:$C$1367,B12,'Scored quarters'!$D$6:$D$1367,C12,'Scored quarters'!$F$6:$F$1367,D12,'Scored quarters'!$G$6:$G$1367,E12)/F12) -> 2.3158154 | H12: =SQRT(SUMIFS('Scored quarters'!$L$6:$L$1367,'Scored quarters'!$C$6:$C$1367,B12,'Scored quarters'!$D$6:$D$1367,C12,'Scored quarters'!$F$6:$F$1367,D12,'Scored quarters'!$G$6:$G$1367,E12)/F12) -> 1.7410485 | I12: =SQRT(SUMIFS('Scored quarters'!$M$6:$M$1367,'Scored quarters'!$C$6:$C$1367,B12,'Scored quarters'!$D$6:$D$1367,C12,'Scored quarters'!$F$6:$F$1367,D12,'Scored quarters'!$G$6:$G$1367,E12)/F12) -> 1.4142136 | J12: =SUMIFS('Scored quarters'!$O$6:$O$1367,'Scored quarters'!$C$6:$C$1367,B12,'Scored quarters'!$D$6:$D$1367,C12,'Scored quarters'!$F$6:$F$1367,D12,'Scored quarters'!$G$6:$G$1367,E12)/F12 -> 1.7398249 | K12: =SUMIFS('Scored quarters'!$J$6:$J$1367,'Scored quarters'!$C$6:$C$1367,B12,'Scored quarters'!$D$6:$D$1367,C12,'Scored quarters'!$F$6:$F$1367,D12,'Scored quarters'!$G$6:$G$1367,E12)/F12 -> -1.7398249 | L12: =SUMIFS('Scored quarters'!$N$6:$N$1367,'Scored quarters'!$C$6:$C$1367,B12,'Scored quarters'!$D$6:$D$1367,C12,'Scored quarters'!$F$6:$F$1367,D12,'Scored quarters'!$G$6:$G$1367,E12) -> 2
B13: Beauty | C13: organic_volume_growth | D13: First month | E13: lagged | F13: =COUNTIFS('Scored quarters'!$C$6:$C$1367,B13,'Scored quarters'!$D$6:$D$1367,C13,'Scored quarters'!$F$6:$F$1367,D13,'Scored quarters'!$G$6:$G$1367,E13) -> 8 | G13: =SQRT(SUMIFS('Scored quarters'!$K$6:$K$1367,'Scored quarters'!$C$6:$C$1367,B13,'Scored quarters'!$D$6:$D$1367,C13,'Scored quarters'!$F$6:$F$1367,D13,'Scored quarters'!$G$6:$G$1367,E13)/F13) -> 2.4015705 | H13: =SQRT(SUMIFS('Scored quarters'!$L$6:$L$1367,'Scored quarters'!$C$6:$C$1367,B13,'Scored quarters'!$D$6:$D$1367,C13,'Scored quarters'!$F$6:$F$1367,D13,'Scored quarters'!$G$6:$G$1367,E13)/F13) -> 1.7410485 | I13: =SQRT(SUMIFS('Scored quarters'!$M$6:$M$1367,'Scored quarters'!$C$6:$C$1367,B13,'Scored quarters'!$D$6:$D$1367,C13,'Scored quarters'!$F$6:$F$1367,D13,'Scored quarters'!$G$6:$G$1367,E13)/F13) -> 1.4142136 | J13: =SUMIFS('Scored quarters'!$O$6:$O$1367,'Scored quarters'!$C$6:$C$1367,B13,'Scored quarters'!$D$6:$D$1367,C13,'Scored quarters'!$F$6:$F$1367,D13,'Scored quarters'!$G$6:$G$1367,E13)/F13 -> 1.9642891 | K13: =SUMIFS('Scored quarters'!$J$6:$J$1367,'Scored quarters'!$C$6:$C$1367,B13,'Scored quarters'!$D$6:$D$1367,C13,'Scored quarters'!$F$6:$F$1367,D13,'Scored quarters'!$G$6:$G$1367,E13)/F13 -> -1.9642891 | L13: =SUMIFS('Scored quarters'!$N$6:$N$1367,'Scored quarters'!$C$6:$C$1367,B13,'Scored quarters'!$D$6:$D$1367,C13,'Scored quarters'!$F$6:$F$1367,D13,'Scored quarters'!$G$6:$G$1367,E13) -> 0
B14: Beauty | C14: organic_volume_growth | D14: First month | E14: blend | F14: =COUNTIFS('Scored quarters'!$C$6:$C$1367,B14,'Scored quarters'!$D$6:$D$1367,C14,'Scored quarters'!$F$6:$F$1367,D14,'Scored quarters'!$G$6:$G$1367,E14) -> 8 | G14: =SQRT(SUMIFS('Scored quarters'!$K$6:$K$1367,'Scored quarters'!$C$6:$C$1367,B14,'Scored quarters'!$D$6:$D$1367,C14,'Scored quarters'!$F$6:$F$1367,D14,'Scored quarters'!$G$6:$G$1367,E14)/F14) -> 2.0101564 | H14: =SQRT(SUMIFS('Scored quarters'!$L$6:$L$1367,'Scored quarters'!$C$6:$C$1367,B14,'Scored quarters'!$D$6:$D$1367,C14,'Scored quarters'!$F$6:$F$1367,D14,'Scored quarters'!$G$6:$G$1367,E14)/F14) -> 1.7410485 | I14: =SQRT(SUMIFS('Scored quarters'!$M$6:$M$1367,'Scored quarters'!$C$6:$C$1367,B14,'Scored quarters'!$D$6:$D$1367,C14,'Scored quarters'!$F$6:$F$1367,D14,'Scored quarters'!$G$6:$G$1367,E14)/F14) -> 1.4142136 | J14: =SUMIFS('Scored quarters'!$O$6:$O$1367,'Scored quarters'!$C$6:$C$1367,B14,'Scored quarters'!$D$6:$D$1367,C14,'Scored quarters'!$F$6:$F$1367,D14,'Scored quarters'!$G$6:$G$1367,E14)/F14 -> 1.4908202 | K14: =SUMIFS('Scored quarters'!$J$6:$J$1367,'Scored quarters'!$C$6:$C$1367,B14,'Scored quarters'!$D$6:$D$1367,C14,'Scored quarters'!$F$6:$F$1367,D14,'Scored quarters'!$G$6:$G$1367,E14)/F14 -> -1.4636625 | L14: =SUMIFS('Scored quarters'!$N$6:$N$1367,'Scored quarters'!$C$6:$C$1367,B14,'Scored quarters'!$D$6:$D$1367,C14,'Scored quarters'!$F$6:$F$1367,D14,'Scored quarters'!$G$6:$G$1367,E14) -> 3
B15: Beauty | C15: organic_volume_growth | D15: Second month | E15: baseline | F15: =COUNTIFS('Scored quarters'!$C$6:$C$1367,B15,'Scored quarters'!$D$6:$D$1367,C15,'Scored quarters'!$F$6:$F$1367,D15,'Scored quarters'!$G$6:$G$1367,E15) -> 8 | G15: =SQRT(SUMIFS('Scored quarters'!$K$6:$K$1367,'Scored quarters'!$C$6:$C$1367,B15,'Scored quarters'!$D$6:$D$1367,C15,'Scored quarters'!$F$6:$F$1367,D15,'Scored quarters'!$G$6:$G$1367,E15)/F15) -> 1.7410485 | H15: =SQRT(SUMIFS('Scored quarters'!$L$6:$L$1367,'Scored quarters'!$C$6:$C$1367,B15,'Scored quarters'!$D$6:$D$1367,C15,'Scored quarters'!$F$6:$F$1367,D15,'Scored quarters'!$G$6:$G$1367,E15)/F15) -> 1.7410485 | I15: =SQRT(SUMIFS('Scored quarters'!$M$6:$M$1367,'Scored quarters'!$C$6:$C$1367,B15,'Scored quarters'!$D$6:$D$1367,C15,'Scored quarters'!$F$6:$F$1367,D15,'Scored quarters'!$G$6:$G$1367,E15)/F15) -> 1.4142136 | J15: =SUMIFS('Scored quarters'!$O$6:$O$1367,'Scored quarters'!$C$6:$C$1367,B15,'Scored quarters'!$D$6:$D$1367,C15,'Scored quarters'!$F$6:$F$1367,D15,'Scored quarters'!$G$6:$G$1367,E15)/F15 -> 1.3125 | K15: =SUMIFS('Scored quarters'!$J$6:$J$1367,'Scored quarters'!$C$6:$C$1367,B15,'Scored quarters'!$D$6:$D$1367,C15,'Scored quarters'!$F$6:$F$1367,D15,'Scored quarters'!$G$6:$G$1367,E15)/F15 -> -1.1875 | L15: =SUMIFS('Scored quarters'!$N$6:$N$1367,'Scored quarters'!$C$6:$C$1367,B15,'Scored quarters'!$D$6:$D$1367,C15,'Scored quarters'!$F$6:$F$1367,D15,'Scored quarters'!$G$6:$G$1367,E15) -> 0
B16: Beauty | C16: organic_volume_growth | D16: Second month | E16: last_actual | F16: =COUNTIFS('Scored quarters'!$C$6:$C$1367,B16,'Scored quarters'!$D$6:$D$1367,C16,'Scored quarters'!$F$6:$F$1367,D16,'Scored quarters'!$G$6:$G$1367,E16) -> 8 | G16: =SQRT(SUMIFS('Scored quarters'!$K$6:$K$1367,'Scored quarters'!$C$6:$C$1367,B16,'Scored quarters'!$D$6:$D$1367,C16,'Scored quarters'!$F$6:$F$1367,D16,'Scored quarters'!$G$6:$G$1367,E16)/F16) -> 1.4142136 | H16: =SQRT(SUMIFS('Scored quarters'!$L$6:$L$1367,'Scored quarters'!$C$6:$C$1367,B16,'Scored quarters'!$D$6:$D$1367,C16,'Scored quarters'!$F$6:$F$1367,D16,'Scored quarters'!$G$6:$G$1367,E16)/F16) -> 1.7410485 | I16: =SQRT(SUMIFS('Scored quarters'!$M$6:$M$1367,'Scored quarters'!$C$6:$C$1367,B16,'Scored quarters'!$D$6:$D$1367,C16,'Scored quarters'!$F$6:$F$1367,D16,'Scored quarters'!$G$6:$G$1367,E16)/F16) -> 1.4142136 | J16: =SUMIFS('Scored quarters'!$O$6:$O$1367,'Scored quarters'!$C$6:$C$1367,B16,'Scored quarters'!$D$6:$D$1367,C16,'Scored quarters'!$F$6:$F$1367,D16,'Scored quarters'!$G$6:$G$1367,E16)/F16 -> 1 | K16: =SUMIFS('Scored quarters'!$J$6:$J$1367,'Scored quarters'!$C$6:$C$1367,B16,'Scored quarters'!$D$6:$D$1367,C16,'Scored quarters'!$F$6:$F$1367,D16,'Scored quarters'!$G$6:$G$1367,E16)/F16 -> -0.5 | L16: =SUMIFS('Scored quarters'!$N$6:$N$1367,'Scored quarters'!$C$6:$C$1367,B16,'Scored quarters'!$D$6:$D$1367,C16,'Scored quarters'!$F$6:$F$1367,D16,'Scored quarters'!$G$6:$G$1367,E16) -> 6
B17: Beauty | C17: organic_volume_growth | D17: Second month | E17: bridge | F17: =COUNTIFS('Scored quarters'!$C$6:$C$1367,B17,'Scored quarters'!$D$6:$D$1367,C17,'Scored quarters'!$F$6:$F$1367,D17,'Scored quarters'!$G$6:$G$1367,E17) -> 8 | G17: =SQRT(SUMIFS('Scored quarters'!$K$6:$K$1367,'Scored quarters'!$C$6:$C$1367,B17,'Scored quarters'!$D$6:$D$1367,C17,'Scored quarters'!$F$6:$F$1367,D17,'Scored quarters'!$G$6:$G$1367,E17)/F17) -> 2.432074 | H17: =SQRT(SUMIFS('Scored quarters'!$L$6:$L$1367,'Scored quarters'!$C$6:$C$1367,B17,'Scored quarters'!$D$6:$D$1367,C17,'Scored quarters'!$F$6:$F$1367,D17,'Scored quarters'!$G$6:$G$1367,E17)/F17) -> 1.7410485 | I17: =SQRT(SUMIFS('Scored quarters'!$M$6:$M$1367,'Scored quarters'!$C$6:$C$1367,B17,'Scored quarters'!$D$6:$D$1367,C17,'Scored quarters'!$F$6:$F$1367,D17,'Scored quarters'!$G$6:$G$1367,E17)/F17) -> 1.4142136 | J17: =SUMIFS('Scored quarters'!$O$6:$O$1367,'Scored quarters'!$C$6:$C$1367,B17,'Scored quarters'!$D$6:$D$1367,C17,'Scored quarters'!$F$6:$F$1367,D17,'Scored quarters'!$G$6:$G$1367,E17)/F17 -> 1.7611425 | K17: =SUMIFS('Scored quarters'!$J$6:$J$1367,'Scored quarters'!$C$6:$C$1367,B17,'Scored quarters'!$D$6:$D$1367,C17,'Scored quarters'!$F$6:$F$1367,D17,'Scored quarters'!$G$6:$G$1367,E17)/F17 -> -1.7611425 | L17: =SUMIFS('Scored quarters'!$N$6:$N$1367,'Scored quarters'!$C$6:$C$1367,B17,'Scored quarters'!$D$6:$D$1367,C17,'Scored quarters'!$F$6:$F$1367,D17,'Scored quarters'!$G$6:$G$1367,E17) -> 3
... B176: Health Care | C176: organic_sales_growth | D176: Pre-earnings | E176: blend | F176: =COUNTIFS('Scored quarters'!$C$6:$C$1367,B176,'Scored quarters'!$D$6:$D$1367,C176,'Scored quarters'!$F$6:$F$1367,D176,'Scored quarters'!$G$6:$G$1367,E176) -> 8 | G176: =SQRT(SUMIFS('Scored quarters'!$K$6:$K$1367,'Scored quarters'!$C$6:$C$1367,B176,'Scored quarters'!$D$6:$D$1367,C176,'Scored quarters'!$F$6:$F$1367,D176,'Scored quarters'!$G$6:$G$1367,E176)/F176) -> 2.3169169 | H176: =SQRT(SUMIFS('Scored quarters'!$L$6:$L$1367,'Scored quarters'!$C$6:$C$1367,B176,'Scored quarters'!$D$6:$D$1367,C176,'Scored quarters'!$F$6:$F$1367,D176,'Scored quarters'!$G$6:$G$1367,E176)/F176) -> 1.118034 | I176: =SQRT(SUMIFS('Scored quarters'!$M$6:$M$1367,'Scored quarters'!$C$6:$C$1367,B176,'Scored quarters'!$D$6:$D$1367,C176,'Scored quarters'!$F$6:$F$1367,D176,'Scored quarters'!$G$6:$G$1367,E176)/F176) -> 1.4142136 | J176: =SUMIFS('Scored quarters'!$O$6:$O$1367,'Scored quarters'!$C$6:$C$1367,B176,'Scored quarters'!$D$6:$D$1367,C176,'Scored quarters'!$F$6:$F$1367,D176,'Scored quarters'!$G$6:$G$1367,E176)/F176 -> 2.1402169 | K176: =SUMIFS('Scored quarters'!$J$6:$J$1367,'Scored quarters'!$C$6:$C$1367,B176,'Scored quarters'!$D$6:$D$1367,C176,'Scored quarters'!$F$6:$F$1367,D176,'Scored quarters'!$G$6:$G$1367,E176)/F176 -> 2.1402169 | L176: =SUMIFS('Scored quarters'!$N$6:$N$1367,'Scored quarters'!$C$6:$C$1367,B176,'Scored quarters'!$D$6:$D$1367,C176,'Scored quarters'!$F$6:$F$1367,D176,'Scored quarters'!$G$6:$G$1367,E176) -> 0

Sheet Scored quarters
B2: Score only after P&G publishes actuals
B5: Forecast ID | C5: Segment | D5: Measure | E5: Quarter | F5: Stage | G5: Method | H5: Prediction | I5: Actual | J5: Error pp | K5: Squared error | L5: Mean error squared | M5: Last actual error squared | N5: Beats mean? | O5: Absolute error
B6: 1 | C6: Beauty | D6: organic_volume_growth | E6: 45473 | F6: Origin | G6: baseline | H6: ='Forecast log'!H6 -> -0.5 | I6: ='PG facts'!D69 -> 1 | J6: =H6-I6 -> -1.5 | K6: =J6^2 -> 2.25 | L6: =('Forecast log'!H6-I6)^2 -> 2.25 | M6: =('Forecast log'!I6-I6)^2 -> 4 | N6: =IF(ABS(J6)<SQRT(L6),1,0) -> 0 | O6: =ABS(J6) -> 1.5
B7: 1 | C7: Beauty | D7: organic_volume_growth | E7: 45473 | F7: Origin | G7: last_actual | H7: ='Forecast log'!I6 -> -1 | I7: ='PG facts'!D69 -> 1 | J7: =H7-I7 -> -2 | K7: =J7^2 -> 4 | L7: =('Forecast log'!H6-I7)^2 -> 2.25 | M7: =('Forecast log'!I6-I7)^2 -> 4 | N7: =IF(ABS(J7)<SQRT(L7),1,0) -> 0 | O7: =ABS(J7) -> 2
B8: 1 | C8: Beauty | D8: organic_volume_growth | E8: 45473 | F8: Origin | G8: bridge | H8: ='Forecast log'!N6 -> -0.95439473 | I8: ='PG facts'!D69 -> 1 | J8: =H8-I8 -> -1.9543947 | K8: =J8^2 -> 3.8196588 | L8: =('Forecast log'!H6-I8)^2 -> 2.25 | M8: =('Forecast log'!I6-I8)^2 -> 4 | N8: =IF(ABS(J8)<SQRT(L8),1,0) -> 0 | O8: =ABS(J8) -> 1.9543947
B9: 1 | C9: Beauty | D9: organic_volume_growth | E9: 45473 | F9: Origin | G9: blend | H9: ='Forecast log'!T6 -> -0.72719737 | I9: ='PG facts'!D69 -> 1 | J9: =H9-I9 -> -1.7271974 | K9: =J9^2 -> 2.9832107 | L9: =('Forecast log'!H6-I9)^2 -> 2.25 | M9: =('Forecast log'!I6-I9)^2 -> 4 | N9: =IF(ABS(J9)<SQRT(L9),1,0) -> 0 | O9: =ABS(J9) -> 1.7271974
B10: 7 | C10: Beauty | D10: organic_volume_growth | E10: 45473 | F10: Pre-earnings | G10: baseline | H10: ='Forecast log'!H12 -> -0.25 | I10: ='PG facts'!D69 -> 1 | J10: =H10-I10 -> -1.25 | K10: =J10^2 -> 1.5625 | L10: =('Forecast log'!H12-I10)^2 -> 1.5625 | M10: =('Forecast log'!I12-I10)^2 -> 0 | N10: =IF(ABS(J10)<SQRT(L10),1,0) -> 0 | O10: =ABS(J10) -> 1.25
B11: 7 | C11: Beauty | D11: organic_volume_growth | E11: 45473 | F11: Pre-earnings | G11: last_actual | H11: ='Forecast log'!I12 -> 1 | I11: ='PG facts'!D69 -> 1 | J11: =H11-I11 -> 0 | K11: =J11^2 -> 0 | L11: =('Forecast log'!H12-I11)^2 -> 1.5625 | M11: =('Forecast log'!I12-I11)^2 -> 0 | N11: =IF(ABS(J11)<SQRT(L11),1,0) -> 1 | O11: =ABS(J11) -> 0
B12: 7 | C12: Beauty | D12: organic_volume_growth | E12: 45473 | F12: Pre-earnings | G12: bridge | H12: ='Forecast log'!N12 -> -0.63217368 | I12: ='PG facts'!D69 -> 1 | J12: =H12-I12 -> -1.6321737 | K12: =J12^2 -> 2.6639909 | L12: =('Forecast log'!H12-I12)^2 -> 1.5625 | M12: =('Forecast log'!I12-I12)^2 -> 0 | N12: =IF(ABS(J12)<SQRT(L12),1,0) -> 0 | O12: =ABS(J12) -> 1.6321737
B13: 7 | C13: Beauty | D13: organic_volume_growth | E13: 45473 | F13: Pre-earnings | G13: lagged | H13: ='Forecast log'!S12 -> -0.9593244 | I13: ='PG facts'!D69 -> 1 | J13: =H13-I13 -> -1.9593244 | K13: =J13^2 -> 3.8389521 | L13: =('Forecast log'!H12-I13)^2 -> 1.5625 | M13: =('Forecast log'!I12-I13)^2 -> 0 | N13: =IF(ABS(J13)<SQRT(L13),1,0) -> 0 | O13: =ABS(J13) -> 1.9593244
B14: 7 | C14: Beauty | D14: organic_volume_growth | E14: 45473 | F14: Pre-earnings | G14: blend | H14: ='Forecast log'!T12 -> -0.44108684 | I14: ='PG facts'!D69 -> 1 | J14: =H14-I14 -> -1.4410868 | K14: =J14^2 -> 2.0767313 | L14: =('Forecast log'!H12-I14)^2 -> 1.5625 | M14: =('Forecast log'!I12-I14)^2 -> 0 | N14: =IF(ABS(J14)<SQRT(L14),1,0) -> 0 | O14: =ABS(J14) -> 1.4410868
B15: 4 | C15: Beauty | D15: organic_volume_growth | E15: 45473 | F15: First month | G15: baseline | H15: ='Forecast log'!H9 -> -0.25 | I15: ='PG facts'!D69 -> 1 | J15: =H15-I15 -> -1.25 | K15: =J15^2 -> 1.5625 | L15: =('Forecast log'!H9-I15)^2 -> 1.5625 | M15: =('Forecast log'!I9-I15)^2 -> 0 | N15: =IF(ABS(J15)<SQRT(L15),1,0) -> 0 | O15: =ABS(J15) -> 1.25
B16: 4 | C16: Beauty | D16: organic_volume_growth | E16: 45473 | F16: First month | G16: last_actual | H16: ='Forecast log'!I9 -> 1 | I16: ='PG facts'!D69 -> 1 | J16: =H16-I16 -> 0 | K16: =J16^2 -> 0 | L16: =('Forecast log'!H9-I16)^2 -> 1.5625 | M16: =('Forecast log'!I9-I16)^2 -> 0 | N16: =IF(ABS(J16)<SQRT(L16),1,0) -> 1 | O16: =ABS(J16) -> 0
B17: 4 | C17: Beauty | D17: organic_volume_growth | E17: 45473 | F17: First month | G17: bridge | H17: ='Forecast log'!N9 -> -0.61787849 | I17: ='PG facts'!D69 -> 1 | J17: =H17-I17 -> -1.6178785 | K17: =J17^2 -> 2.6175308 | L17: =('Forecast log'!H9-I17)^2 -> 1.5625 | M17: =('Forecast log'!I9-I17)^2 -> 0 | N17: =IF(ABS(J17)<SQRT(L17),1,0) -> 0 | O17: =ABS(J17) -> 1.6178785
B18: 4 | C18: Beauty | D18: organic_volume_growth | E18: 45473 | F18: First month | G18: lagged | H18: ='Forecast log'!S9 -> -0.9542201 | I18: ='PG facts'!D69 -> 1 | J18: =H18-I18 -> -1.9542201 | K18: =J18^2 -> 3.8189762 | L18: =('Forecast log'!H9-I18)^2 -> 1.5625 | M18: =('Forecast log'!I9-I18)^2 -> 0 | N18: =IF(ABS(J18)<SQRT(L18),1,0) -> 0 | O18: =ABS(J18) -> 1.9542201
B19: 4 | C19: Beauty | D19: organic_volume_growth | E19: 45473 | F19: First month | G19: blend | H19: ='Forecast log'!T9 -> -0.43393925 | I19: ='PG facts'!D69 -> 1 | J19: =H19-I19 -> -1.4339392 | K19: =J19^2 -> 2.0561818 | L19: =('Forecast log'!H9-I19)^2 -> 1.5625 | M19: =('Forecast log'!I9-I19)^2 -> 0 | N19: =IF(ABS(J19)<SQRT(L19),1,0) -> 0 | O19: =ABS(J19) -> 1.4339392
B20: 5 | C20: Beauty | D20: organic_volume_growth | E20: 45473 | F20: Second month | G20: baseline | H20: ='Forecast log'!H10 -> -0.25 | I20: ='PG facts'!D69 -> 1 | J20: =H20-I20 -> -1.25 | K20: =J20^2 -> 1.5625 | L20: =('Forecast log'!H10-I20)^2 -> 1.5625 | M20: =('Forecast log'!I10-I20)^2 -> 0 | N20: =IF(ABS(J20)<SQRT(L20),1,0) -> 0 | O20: =ABS(J20) -> 1.25
B21: 5 | C21: Beauty | D21: organic_volume_growth | E21: 45473 | F21: Second month | G21: last_actual | H21: ='Forecast log'!I10 -> 1 | I21: ='PG facts'!D69 -> 1 | J21: =H21-I21 -> 0 | K21: =J21^2 -> 0 | L21: =('Forecast log'!H10-I21)^2 -> 1.5625 | M21: =('Forecast log'!I10-I21)^2 -> 0 | N21: =IF(ABS(J21)<SQRT(L21),1,0) -> 1 | O21: =ABS(J21) -> 0
B22: 5 | C22: Beauty | D22: organic_volume_growth | E22: 45473 | F22: Second month | G22: bridge | H22: ='Forecast log'!N10 -> -0.70010948 | I22: ='PG facts'!D69 -> 1 | J22: =H22-I22 -> -1.7001095 | K22: =J22^2 -> 2.8903722 | L22: =('Forecast log'!H10-I22)^2 -> 1.5625 | M22: =('Forecast log'!I10-I22)^2 -> 0 | N22: =IF(ABS(J22)<SQRT(L22),1,0) -> 0 | O22: =ABS(J22) -> 1.7001095
B23: 5 | C23: Beauty | D23: organic_volume_growth | E23: 45473 | F23: Second month | G23: lagged | H23: ='Forecast log'!S10 -> -0.9593244 | I23: ='PG facts'!D69 -> 1 | J23: =H23-I23 -> -1.9593244 | K23: =J23^2 -> 3.8389521 | L23: =('Forecast log'!H10-I23)^2 -> 1.5625 | M23: =('Forecast log'!I10-I23)^2 -> 0 | N23: =IF(ABS(J23)<SQRT(L23),1,0) -> 0 | O23: =ABS(J23) -> 1.9593244
B24: 5 | C24: Beauty | D24: organic_volume_growth | E24: 45473 | F24: Second month | G24: blend | H24: ='Forecast log'!T10 -> -0.47505474 | I24: ='PG facts'!D69 -> 1 | J24: =H24-I24 -> -1.4750547 | K24: =J24^2 -> 2.1757865 | L24: =('Forecast log'!H10-I24)^2 -> 1.5625 | M24: =('Forecast log'!I10-I24)^2 -> 0 | N24: =IF(ABS(J24)<SQRT(L24),1,0) -> 0 | O24: =ABS(J24) -> 1.4750547
B25: 66 | C25: Beauty | D25: organic_volume_growth | E25: 45565 | F25: Origin | G25: baseline | H25: ='Forecast log'!H71 -> -0.25 | I25: ='PG facts'!D76 -> 0 | J25: =H25-I25 -> -0.25 | K25: =J25^2 -> 0.0625 | L25: =('Forecast log'!H71-I25)^2 -> 0.0625 | M25: =('Forecast log'!I71-I25)^2 -> 1 | N25: =IF(ABS(J25)<SQRT(L25),1,0) -> 0 | O25: =ABS(J25) -> 0.25
B26: 66 | C26: Beauty | D26: organic_volume_growth | E26: 45565 | F26: Origin | G26: last_actual | H26: ='Forecast log'!I71 -> 1 | I26: ='PG facts'!D76 -> 0 | J26: =H26-I26 -> 1 | K26: =J26^2 -> 1 | L26: =('Forecast log'!H71-I26)^2 -> 0.0625 | M26: =('Forecast log'!I71-I26)^2 -> 1 | N26: =IF(ABS(J26)<SQRT(L26),1,0) -> 0 | O26: =ABS(J26) -> 1
B27: 66 | C27: Beauty | D27: organic_volume_growth | E27: 45565 | F27: Origin | G27: bridge | H27: ='Forecast log'!N71 -> -0.6071972 | I27: ='PG facts'!D76 -> 0 | J27: =H27-I27 -> -0.6071972 | K27: =J27^2 -> 0.36868844 | L27: =('Forecast log'!H71-I27)^2 -> 0.0625 | M27: =('Forecast log'!I71-I27)^2 -> 1 | N27: =IF(ABS(J27)<SQRT(L27),1,0) -> 0 | O27: =ABS(J27) -> 0.6071972
B28: 66 | C28: Beauty | D28: organic_volume_growth | E28: 45565 | F28: Origin | G28: blend | H28: ='Forecast log'!T71 -> -0.4285986 | I28: ='PG facts'!D76 -> 0 | J28: =H28-I28 -> -0.4285986 | K28: =J28^2 -> 0.18369676 | L28: =('Forecast log'!H71-I28)^2 -> 0.0625 | M28: =('Forecast log'!I71-I28)^2 -> 1 | N28: =IF(ABS(J28)<SQRT(L28),1,0) -> 0 | O28: =ABS(J28) -> 0.4285986
B29: 71 | C29: Beauty | D29: organic_volume_growth | E29: 45565 | F29: Pre-earnings | G29: baseline | H29: ='Forecast log'!H76 -> 0.25 | I29: ='PG facts'!D76 -> 0 | J29: =H29-I29 -> 0.25 | K29: =J29^2 -> 0.0625 | L29: =('Forecast log'!H76-I29)^2 -> 0.0625 | M29: =('Forecast log'!I76-I29)^2 -> 1 | N29: =IF(ABS(J29)<SQRT(L29),1,0) -> 0 | O29: =ABS(J29) -> 0.25
B30: 71 | C30: Beauty | D30: organic_volume_growth | E30: 45565 | F30: Pre-earnings | G30: last_actual | H30: ='Forecast log'!I76 -> 1 | I30: ='PG facts'!D76 -> 0 | J30: =H30-I30 -> 1 | K30: =J30^2 -> 1 | L30: =('Forecast log'!H76-I30)^2 -> 0.0625 | M30: =('Forecast log'!I76-I30)^2 -> 1 | N30: =IF(ABS(J30)<SQRT(L30),1,0) -> 0 | O30: =ABS(J30) -> 1
B31: 71 | C31: Beauty | D31: organic_volume_growth | E31: 45565 | F31: Pre-earnings | G31: bridge | H31: ='Forecast log'!N76 -> -0.051498095 | I31: ='PG facts'!D76 -> 0 | J31: =H31-I31 -> -0.051498095 | K31: =J31^2 -> 0.0026520538 | L31: =('Forecast log'!H76-I31)^2 -> 0.0625 | M31: =('Forecast log'!I76-I31)^2 -> 1 | N31: =IF(ABS(J31)<SQRT(L31),1,0) -> 1 | O31: =ABS(J31) -> 0.051498095
B32: 71 | C32: Beauty | D32: organic_volume_growth | E32: 45565 | F32: Pre-earnings | G32: lagged | H32: ='Forecast log'!S76 -> -0.53242653 | I32: ='PG facts'!D76 -> 0 | J32: =H32-I32 -> -0.53242653 | K32: =J32^2 -> 0.28347801 | L32: =('Forecast log'!H76-I32)^2 -> 0.0625 | M32: =('Forecast log'!I76-I32)^2 -> 1 | N32: =IF(ABS(J32)<SQRT(L32),1,0) -> 0 | O32: =ABS(J32) -> 0.53242653
B33: 71 | C33: Beauty | D33: organic_volume_growth | E33: 45565 | F33: Pre-earnings | G33: blend | H33: ='Forecast log'!T76 -> 0.099250953 | I33: ='PG facts'!D76 -> 0 | J33: =H33-I33 -> 0.099250953 | K33: =J33^2 -> 0.0098507516 | L33: =('Forecast log'!H76-I33)^2 -> 0.0625 | M33: =('Forecast log'!I76-I33)^2 -> 1 | N33: =IF(ABS(J33)<SQRT(L33),1,0) -> 1 | O33: =ABS(J33) -> 0.099250953
B34: 69 | C34: Beauty | D34: organic_volume_growth | E34: 45565 | F34: First month | G34: baseline | H34: ='Forecast log'!H74 -> 0.25 | I34: ='PG facts'!D76 -> 0 | J34: =H34-I34 -> 0.25 | K34: =J34^2 -> 0.0625 | L34: =('Forecast log'!H74-I34)^2 -> 0.0625 | M34: =('Forecast log'!I74-I34)^2 -> 1 | N34: =IF(ABS(J34)<SQRT(L34),1,0) -> 0 | O34: =ABS(J34) -> 0.25
B35: 69 | C35: Beauty | D35: organic_volume_growth | E35: 45565 | F35: First month | G35: last_actual | H35: ='Forecast log'!I74 -> 1 | I35: ='PG facts'!D76 -> 0 | J35: =H35-I35 -> 1 | K35: =J35^2 -> 1 | L35: =('Forecast log'!H74-I35)^2 -> 0.0625 | M35: =('Forecast log'!I74-I35)^2 -> 1 | N35: =IF(ABS(J35)<SQRT(L35),1,0) -> 0 | O35: =ABS(J35) -> 1
B36: 69 | C36: Beauty | D36: organic_volume_growth | E36: 45565 | F36: First month | G36: bridge | H36: ='Forecast log'!N74 -> -0.34776572 | I36: ='PG facts'!D76 -> 0 | J36: =H36-I36 -> -0.34776572 | K36: =J36^2 -> 0.12094099 | L36: =('Forecast log'!H74-I36)^2 -> 0.0625 | M36: =('Forecast log'!I74-I36)^2 -> 1 | N36: =IF(ABS(J36)<SQRT(L36),1,0) -> 0 | O36: =ABS(J36) -> 0.34776572
B37: 69 | C37: Beauty | D37: organic_volume_growth | E37: 45565 | F37: First month | G37: lagged | H37: ='Forecast log'!S74 -> -0.63678505 | I37: ='PG facts'!D76 -> 0 | J37: =H37-I37 -> -0.63678505 | K37: =J37^2 -> 0.4054952 | L37: =('Forecast log'!H74-I37)^2 -> 0.0625 | M37: =('Forecast log'!I74-I37)^2 -> 1 | N37: =IF(ABS(J37)<SQRT(L37),1,0) -> 0 | O37: =ABS(J37) -> 0.63678505
B38: 69 | C38: Beauty | D38: organic_volume_growth | E38: 45565 | F38: First month | G38: blend | H38: ='Forecast log'!T74 -> -0.048882858 | I38: ='PG facts'!D76 -> 0 | J38: =H38-I38 -> -0.048882858 | K38: =J38^2 -> 0.0023895338 | L38: =('Forecast log'!H74-I38)^2 -> 0.0625 | M38: =('Forecast log'!I74-I38)^2 -> 1 | N38: =IF(ABS(J38)<SQRT(L38),1,0) -> 1 | O38: =ABS(J38) -> 0.048882858
B39: 70 | C39: Beauty | D39: organic_volume_growth | E39: 45565 | F39: Second month | G39: baseline | H39: ='Forecast log'!H75 -> 0.25 | I39: ='PG facts'!D76 -> 0 | J39: =H39-I39 -> 0.25 | K39: =J39^2 -> 0.0625 | L39: =('Forecast log'!H75-I39)^2 -> 0.0625 | M39: =('Forecast log'!I75-I39)^2 -> 1 | N39: =IF(ABS(J39)<SQRT(L39),1,0) -> 0 | O39: =ABS(J39) -> 0.25
B40: 70 | C40: Beauty | D40: organic_volume_growth | E40: 45565 | F40: Second month | G40: last_actual | H40: ='Forecast log'!I75 -> 1 | I40: ='PG facts'!D76 -> 0 | J40: =H40-I40 -> 1 | K40: =J40^2 -> 1 | L40: =('Forecast log'!H75-I40)^2 -> 0.0625 | M40: =('Forecast log'!I75-I40)^2 -> 1 | N40: =IF(ABS(J40)<SQRT(L40),1,0) -> 0 | O40: =ABS(J40) -> 1
B41: 70 | C41: Beauty | D41: organic_volume_growth | E41: 45565 | F41: Second month | G41: bridge | H41: ='Forecast log'!N75 -> -0.051498095 | I41: ='PG facts'!D76 -> 0 | J41: =H41-I41 -> -0.051498095 | K41: =J41^2 -> 0.0026520538 | L41: =('Forecast log'!H75-I41)^2 -> 0.0625 | M41: =('Forecast log'!I75-I41)^2 -> 1 | N41: =IF(ABS(J41)<SQRT(L41),1,0) -> 1 | O41: =ABS(J41) -> 0.051498095
B42: 70 | C42: Beauty | D42: organic_volume_growth | E42: 45565 | F42: Second month | G42: lagged | H42: ='Forecast log'!S75 -> -0.53242653 | I42: ='PG facts'!D76 -> 0 | J42: =H42-I42 -> -0.53242653 | K42: =J42^2 -> 0.28347801 | L42: =('Forecast log'!H75-I42)^2 -> 0.0625 | M42: =('Forecast log'!I75-I42)^2 -> 1 | N42: =IF(ABS(J42)<SQRT(L42),1,0) -> 0 | O42: =ABS(J42) -> 0.53242653
B43: 70 | C43: Beauty | D43: organic_volume_growth | E43: 45565 | F43: Second month | G43: blend | H43: ='Forecast log'!T75 -> 0.099250953 | I43: ='PG facts'!D76 -> 0 | J43: =H43-I43 -> 0.099250953 | K43: =J43^2 -> 0.0098507516 | L43: =('Forecast log'!H75-I43)^2 -> 0.0625 | M43: =('Forecast log'!I75-I43)^2 -> 1 | N43: =IF(ABS(J43)<SQRT(L43),1,0) -> 1 | O43: =ABS(J43) -> 0.099250953
...

Sheet Forecast log
B2: Release-by-release forecast calculations
B3: Download / calendar alignment runs in Python. Excel recalculates fitted coefficients, forecasts and scores.
B5: ID | C5: Segment | D5: Measure | E5: Target quarter | F5: Known by | G5: Observed months | H5: Four-quarter mean | I5: Last actual | J5: Bridge n | K5: Bridge slope | L5: Bridge intercept | M5: Market nowcast % | N5: Bridge result | O5: Lag n | P5: Lag slope | Q5: Lag intercept | R5: Prior-quarter market % | S5: Lag result | T5: 50/50 blend | U5: Market version | V5: Latest P&G publication | W5: Market source
B6: 1 | C6: Beauty | D6: organic_volume_growth | E6: 45473 | F6: 45383 | G6: 0 | H6: =AVERAGE('PG facts'!D34,'PG facts'!D41,'PG facts'!D48,'PG facts'!D55) -> -0.5 | I6: ='PG facts'!D55 -> -1 | J6: =COUNT('Training pairs'!F6:F13) -> 8 | K6: =(SUM('Training pairs'!I6:I13)-SUM('Training pairs'!F6:F13)*SUM('Training pairs'!G6:G13)/COUNT('Training pairs'!F6:F13))/(SUM('Training pairs'!H6:H13)-SUM('Training pairs'!F6:F13)^2/COUNT('Training pairs'!F6:F13)) -> 0.31709936 | L6: =AVERAGE('Training pairs'!G6:G13)-K6*AVERAGE('Training pairs'!F6:F13) -> -1.4839268 | M6: =(SUM('Target months'!H6:H8)/SUM('Target months'!F6:F8)-1)*100 -> 1.6699249 | N6: =L6+K6*M6 -> -0.95439473 | O6: ="n.a." -> n.a. | P6: ="n.a." -> n.a. | Q6: ="n.a." -> n.a. | R6: n.a. | S6: ="n.a." -> n.a. | T6: =(H6+N6)/2 -> -0.72719737 | U6: 45383 | V6: 45314 | W6: https://alfred.stlouisfed.org/graph/alfredgraph.csv?id=PCENDC96&cosd=2021-01-01&coed=2026-04-01&vintage_date=2024-04-01
B7: 2 | C7: Beauty | D7: organic_volume_growth | E7: 45473 | F7: 45401 | G7: 0 | H7: =AVERAGE('PG facts'!D41,'PG facts'!D48,'PG facts'!D55,'PG facts'!D62) -> -0.25 | I7: ='PG facts'!D62 -> 1 | J7: =COUNT('Training pairs'!F21:F28) -> 8 | K7: =(SUM('Training pairs'!I21:I28)-SUM('Training pairs'!F21:F28)*SUM('Training pairs'!G21:G28)/COUNT('Training pairs'!F21:F28))/(SUM('Training pairs'!H21:H28)-SUM('Training pairs'!F21:F28)^2/COUNT('Training pairs'!F21:F28)) -> 0.31709936 | L7: =AVERAGE('Training pairs'!G21:G28)-K7*AVERAGE('Training pairs'!F21:F28) -> -1.4839268 | M7: =(SUM('Target months'!H9:H11)/SUM('Target months'!F9:F11)-1)*100 -> 1.6699249 | N7: =L7+K7*M7 -> -0.95439473 | O7: =COUNT('Training pairs'!F29:F36) -> 8 | P7: =(SUM('Training pairs'!I29:I36)-SUM('Training pairs'!F29:F36)*SUM('Training pairs'!G29:G36)/COUNT('Training pairs'!F29:F36))/(SUM('Training pairs'!H29:H36)-SUM('Training pairs'!F29:F36)^2/COUNT('Training pairs'!F29:F36)) -> 0.045498424 | Q7: =AVERAGE('Training pairs'!G29:G36)-P7*AVERAGE('Training pairs'!F29:F36) -> -1.0335646 | R7: n.a. | S7: ="n.a." -> n.a. | T7: =(H7+N7)/2 -> -0.60219737 | U7: 45383 | V7: 45401 | W7: https://alfred.stlouisfed.org/graph/alfredgraph.csv?id=PCENDC96&cosd=2021-01-01&coed=2026-04-01&vintage_date=2024-04-01
B8: 3 | C8: Beauty | D8: organic_volume_growth | E8: 45473 | F8: 45408 | G8: 0 | H8: =AVERAGE('PG facts'!D41,'PG facts'!D48,'PG facts'!D55,'PG facts'!D62) -> -0.25 | I8: ='PG facts'!D62 -> 1 | J8: =COUNT('Training pairs'!F37:F45) -> 9 | K8: =(SUM('Training pairs'!I37:I45)-SUM('Training pairs'!F37:F45)*SUM('Training pairs'!G37:G45)/COUNT('Training pairs'!F37:F45))/(SUM('Training pairs'!H37:H45)-SUM('Training pairs'!F37:F45)^2/COUNT('Training pairs'!F37:F45)) -> 0.42335534 | L8: =AVERAGE('Training pairs'!G37:G45)-K8*AVERAGE('Training pairs'!F37:F45) -> -1.367135 | M8: =(SUM('Target months'!H12:H14)/SUM('Target months'!F12:F14)-1)*100 -> 1.9054357 | N8: =L8+K8*M8 -> -0.56045861 | O8: =COUNT('Training pairs'!F46:F53) -> 8 | P8: =(SUM('Training pairs'!I46:I53)-SUM('Training pairs'!F46:F53)*SUM('Training pairs'!G46:G53)/COUNT('Training pairs'!F46:F53))/(SUM('Training pairs'!H46:H53)-SUM('Training pairs'!F46:F53)^2/COUNT('Training pairs'!F46:F53)) -> 0.045498424 | Q8: =AVERAGE('Training pairs'!G46:G53)-P8*AVERAGE('Training pairs'!F46:F53) -> -1.0335646 | R8: 1.9031592 | S8: =Q8+P8*R8 -> -0.94697382 | T8: =(H8+N8)/2 -> -0.40522931 | U8: 45408 | V8: 45401 | W8: https://alfred.stlouisfed.org/graph/alfredgraph.csv?id=PCENDC96&cosd=2021-01-01&coed=2026-04-01&vintage_date=2024-04-26
B9: 4 | C9: Beauty | D9: organic_volume_growth | E9: 45473 | F9: 45443 | G9: 1 | H9: =AVERAGE('PG facts'!D41,'PG facts'!D48,'PG facts'!D55,'PG facts'!D62) -> -0.25 | I9: ='PG facts'!D62 -> 1 | J9: =COUNT('Training pairs'!F54:F62) -> 9 | K9: =(SUM('Training pairs'!I54:I62)-SUM('Training pairs'!F54:F62)*SUM('Training pairs'!G54:G62)/COUNT('Training pairs'!F54:F62))/(SUM('Training pairs'!H54:H62)-SUM('Training pairs'!F54:F62)^2/COUNT('Training pairs'!F54:F62)) -> 0.41290525 | L9: =AVERAGE('Training pairs'!G54:G62)-K9*AVERAGE('Training pairs'!F54:F62) -> -1.3507658 | M9: =(SUM('Target months'!H15:H17)/SUM('Target months'!F15:F17)-1)*100 -> 1.7749528 | N9: =L9+K9*M9 -> -0.61787849 | O9: =COUNT('Training pairs'!F63:F70) -> 8 | P9: =(SUM('Training pairs'!I63:I70)-SUM('Training pairs'!F63:F70)*SUM('Training pairs'!G63:G70)/COUNT('Training pairs'!F63:F70))/(SUM('Training pairs'!H63:H70)-SUM('Training pairs'!F63:F70)^2/COUNT('Training pairs'!F63:F70)) -> 0.045498424 | Q9: =AVERAGE('Training pairs'!G63:G70)-P9*AVERAGE('Training pairs'!F63:F70) -> -1.0335646 | R9: 1.7438949 | S9: =Q9+P9*R9 -> -0.9542201 | T9: =(H9+N9)/2 -> -0.43393925 | U9: 45443 | V9: 45401 | W9: https://alfred.stlouisfed.org/graph/alfredgraph.csv?id=PCENDC96&cosd=2021-01-01&coed=2026-04-01&vintage_date=2024-05-31
B10: 5 | C10: Beauty | D10: organic_volume_growth | E10: 45473 | F10: 45471 | G10: 2 | H10: =AVERAGE('PG facts'!D41,'PG facts'!D48,'PG facts'!D55,'PG facts'!D62) -> -0.25 | I10: ='PG facts'!D62 -> 1 | J10: =COUNT('Training pairs'!F71:F79) -> 9 | K10: =(SUM('Training pairs'!I71:I79)-SUM('Training pairs'!F71:F79)*SUM('Training pairs'!G71:G79)/COUNT('Training pairs'!F71:F79))/(SUM('Training pairs'!H71:H79)-SUM('Training pairs'!F71:F79)^2/COUNT('Training pairs'!F71:F79)) -> 0.40471248 | L10: =AVERAGE('Training pairs'!G71:G79)-K10*AVERAGE('Training pairs'!F71:F79) -> -1.3387612 | M10: =(SUM('Target months'!H18:H20)/SUM('Target months'!F18:F20)-1)*100 -> 1.5780382 | N10: =L10+K10*M10 -> -0.70010948 | O10: =COUNT('Training pairs'!F80:F87) -> 8 | P10: =(SUM('Training pairs'!I80:I87)-SUM('Training pairs'!F80:F87)*SUM('Training pairs'!G80:G87)/COUNT('Training pairs'!F80:F87))/(SUM('Training pairs'!H80:H87)-SUM('Training pairs'!F80:F87)^2/COUNT('Training pairs'!F80:F87)) -> 0.045498424 | Q10: =AVERAGE('Training pairs'!G80:G87)-P10*AVERAGE('Training pairs'!F80:F87) -> -1.0335646 | R10: 1.6317086 | S10: =Q10+P10*R10 -> -0.9593244 | T10: =(H10+N10)/2 -> -0.47505474 | U10: 45471 | V10: 45401 | W10: https://alfred.stlouisfed.org/graph/alfredgraph.csv?id=PCENDC96&cosd=2021-01-01&coed=2026-04-01&vintage_date=2024-06-28
B11: 6 | C11: Beauty | D11: organic_volume_growth | E11: 45473 | F11: 45499 | G11: 3 | H11: =AVERAGE('PG facts'!D41,'PG facts'!D48,'PG facts'!D55,'PG facts'!D62) -> -0.25 | I11: ='PG facts'!D62 -> 1 | J11: =COUNT('Training pairs'!F88:F96) -> 9 | K11: =(SUM('Training pairs'!I88:I96)-SUM('Training pairs'!F88:F96)*SUM('Training pairs'!G88:G96)/COUNT('Training pairs'!F88:F96))/(SUM('Training pairs'!H88:H96)-SUM('Training pairs'!F88:F96)^2/COUNT('Training pairs'!F88:F96)) -> 0.40471248 | L11: =AVERAGE('Training pairs'!G88:G96)-K11*AVERAGE('Training pairs'!F88:F96) -> -1.3387612 | M11: =(SUM('Target months'!H21:H23)/SUM('Target months'!F21:F23)-1)*100 -> 1.7459001 | N11: =L11+K11*M11 -> -0.63217368 | O11: =COUNT('Training pairs'!F97:F104) -> 8 | P11: =(SUM('Training pairs'!I97:I104)-SUM('Training pairs'!F97:F104)*SUM('Training pairs'!G97:G104)/COUNT('Training pairs'!F97:F104))/(SUM('Training pairs'!H97:H104)-SUM('Training pairs'!F97:F104)^2/COUNT('Training pairs'!F97:F104)) -> 0.045498424 | Q11: =AVERAGE('Training pairs'!G97:G104)-P11*AVERAGE('Training pairs'!F97:F104) -> -1.0335646 | R11: 1.6317086 | S11: =Q11+P11*R11 -> -0.9593244 | T11: =(H11+N11)/2 -> -0.44108684 | U11: 45499 | V11: 45401 | W11: https://alfred.stlouisfed.org/graph/alfredgraph.csv?id=PCENDC96&cosd=2021-01-01&coed=2026-04-01&vintage_date=2024-07-26
B12: 7 | C12: Beauty | D12: organic_volume_growth | E12: 45473 | F12: 45502 | G12: 3 | H12: =AVERAGE('PG facts'!D41,'PG facts'!D48,'PG facts'!D55,'PG facts'!D62) -> -0.25 | I12: ='PG facts'!D62 -> 1 | J12: =COUNT('Training pairs'!F105:F113) -> 9 | K12: =(SUM('Training pairs'!I105:I113)-SUM('Training pairs'!F105:F113)*SUM('Training pairs'!G105:G113)/COUNT('Training pairs'!F105:F113))/(SUM('Training pairs'!H105:H113)-SUM('Training pairs'!F105:F113)^2/COUNT('Training pairs'!F105:F113)) -> 0.40471248 | L12: =AVERAGE('Training pairs'!G105:G113)-K12*AVERAGE('Training pairs'!F105:F113) -> -1.3387612 | M12: =(SUM('Target months'!H24:H26)/SUM('Target months'!F24:F26)-1)*100 -> 1.7459001 | N12: =L12+K12*M12 -> -0.63217368 | O12: =COUNT('Training pairs'!F114:F121) -> 8 | P12: =(SUM('Training pairs'!I114:I121)-SUM('Training pairs'!F114:F121)*SUM('Training pairs'!G114:G121)/COUNT('Training pairs'!F114:F121))/(SUM('Training pairs'!H114:H121)-SUM('Training pairs'!F114:F121)^2/COUNT('Training pairs'!F114:F121)) -> 0.045498424 | Q12: =AVERAGE('Training pairs'!G114:G121)-P12*AVERAGE('Training pairs'!F114:F121) -> -1.0335646 | R12: 1.6317086 | S12: =Q12+P12*R12 -> -0.9593244 | T12: =(H12+N12)/2 -> -0.44108684 | U12: 45499 | V12: 45401 | W12: https://alfred.stlouisfed.org/graph/alfredgraph.csv?id=PCENDC96&cosd=2021-01-01&coed=2026-04-01&vintage_date=2024-07-26
B13: 8 | C13: Grooming | D13: organic_volume_growth | E13: 45473 | F13: 45383 | G13: 0 | H13: =AVERAGE('PG facts'!D35,'PG facts'!D42,'PG facts'!D49,'PG facts'!D56) -> -0.75 | I13: ='PG facts'!D56 -> 1 | J13: =COUNT('Training pairs'!F122:F129) -> 8 | K13: =(SUM('Training pairs'!I122:I129)-SUM('Training pairs'!F122:F129)*SUM('Training pairs'!G122:G129)/COUNT('Training pairs'!F122:F129))/(SUM('Training pairs'!H122:H129)-SUM('Training pairs'!F122:F129)^2/COUNT('Training pairs'!F122:F129)) -> 1.0507367 | L13: =AVERAGE('Training pairs'!G122:G129)-K13*AVERAGE('Training pairs'!F122:F129) -> -2.1501372 | M13: =(SUM('Target months'!H27:H29)/SUM('Target months'!F27:F29)-1)*100 -> 1.6699249 | N13: =L13+K13*M13 -> -0.39548585 | O13: ="n.a." -> n.a. | P13: ="n.a." -> n.a. | Q13: ="n.a." -> n.a. | R13: n.a. | S13: ="n.a." -> n.a. | T13: =(H13+N13)/2 -> -0.57274293 | U13: 45383 | V13: 45314 | W13: https://alfred.stlouisfed.org/graph/alfredgraph.csv?id=PCENDC96&cosd=2021-01-01&coed=2026-04-01&vintage_date=2024-04-01
B14: 9 | C14: Grooming | D14: organic_volume_growth | E14: 45473 | F14: 45401 | G14: 0 | H14: =AVERAGE('PG facts'!D42,'PG facts'!D49,'PG facts'!D56,'PG facts'!D63) -> 0 | I14: ='PG facts'!D63 -> 2 | J14: =COUNT('Training pairs'!F137:F144) -> 8 | K14: =(SUM('Training pairs'!I137:I144)-SUM('Training pairs'!F137:F144)*SUM('Training pairs'!G137:G144)/COUNT('Training pairs'!F137:F144))/(SUM('Training pairs'!H137:H144)-SUM('Training pairs'!F137:F144)^2/COUNT('Training pairs'!F137:F144)) -> 1.0507367 | L14: =AVERAGE('Training pairs'!G137:G144)-K14*AVERAGE('Training pairs'!F137:F144) -> -2.1501372 | M14: =(SUM('Target months'!H30:H32)/SUM('Target months'!F30:F32)-1)*100 -> 1.6699249 | N14: =L14+K14*M14 -> -0.39548585 | O14: =COUNT('Training pairs'!F145:F152) -> 8 | P14: =(SUM('Training pairs'!I145:I152)-SUM('Training pairs'!F145:F152)*SUM('Training pairs'!G145:G152)/COUNT('Training pairs'!F145:F152))/(SUM('Training pairs'!H145:H152)-SUM('Training pairs'!F145:F152)^2/COUNT('Training pairs'!F145:F152)) -> 0.60069365 | Q14: =AVERAGE('Training pairs'!G145:G152)-P14*AVERAGE('Training pairs'!F145:F152) -> -1.6931367 | R14: n.a. | S14: ="n.a." -> n.a. | T14: =(H14+N14)/2 -> -0.19774293 | U14: 45383 | V14: 45401 | W14: https://alfred.stlouisfed.org/graph/alfredgraph.csv?id=PCENDC96&cosd=2021-01-01&coed=2026-04-01&vintage_date=2024-04-01
B15: 10 | C15: Grooming | D15: organic_volume_growth | E15: 45473 | F15: 45408 | G15: 0 | H15: =AVERAGE('PG facts'!D42,'PG facts'!D49,'PG facts'!D56,'PG facts'!D63) -> 0 | I15: ='PG facts'!D63 -> 2 | J15: =COUNT('Training pairs'!F153:F161) -> 9 | K15: =(SUM('Training pairs'!I153:I161)-SUM('Training pairs'!F153:F161)*SUM('Training pairs'!G153:G161)/COUNT('Training pairs'!F153:F161))/(SUM('Training pairs'!H153:H161)-SUM('Training pairs'!F153:F161)^2/COUNT('Training pairs'!F153:F161)) -> 1.1722483 | L15: =AVERAGE('Training pairs'!G153:G161)-K15*AVERAGE('Training pairs'!F153:F161) -> -2.0165771 | M15: =(SUM('Target months'!H33:H35)/SUM('Target months'!F33:F35)-1)*100 -> 1.9054357 | N15: =L15+K15*M15 -> 0.2170666 | O15: =COUNT('Training pairs'!F162:F169) -> 8 | P15: =(SUM('Training pairs'!I162:I169)-SUM('Training pairs'!F162:F169)*SUM('Training pairs'!G162:G169)/COUNT('Training pairs'!F162:F169))/(SUM('Training pairs'!H162:H169)-SUM('Training pairs'!F162:F169)^2/COUNT('Training pairs'!F162:F169)) -> 0.60069365 | Q15: =AVERAGE('Training pairs'!G162:G169)-P15*AVERAGE('Training pairs'!F162:F169) -> -1.6931367 | R15: 1.9031592 | S15: =Q15+P15*R15 -> -0.54992105 | T15: =(H15+N15)/2 -> 0.1085333 | U15: 45408 | V15: 45401 | W15: https://alfred.stlouisfed.org/graph/alfredgraph.csv?id=PCENDC96&cosd=2021-01-01&coed=2026-04-01&vintage_date=2024-04-26
B16: 11 | C16: Grooming | D16: organic_volume_growth | E16: 45473 | F16: 45443 | G16: 1 | H16: =AVERAGE('PG facts'!D42,'PG facts'!D49,'PG facts'!D56,'PG facts'!D63) -> 0 | I16: ='PG facts'!D63 -> 2 | J16: =COUNT('Training pairs'!F170:F178) -> 9 | K16: =(SUM('Training pairs'!I170:I178)-SUM('Training pairs'!F170:F178)*SUM('Training pairs'!G170:G178)/COUNT('Training pairs'!F170:F178))/(SUM('Training pairs'!H170:H178)-SUM('Training pairs'!F170:F178)^2/COUNT('Training pairs'!F170:F178)) -> 1.1657354 | L16: =AVERAGE('Training pairs'!G170:G178)-K16*AVERAGE('Training pairs'!F170:F178) -> -1.9903002 | M16: =(SUM('Target months'!H36:H38)/SUM('Target months'!F36:F38)-1)*100 -> 1.7749528 | N16: =L16+K16*M16 -> 0.0788251 | O16: =COUNT('Training pairs'!F179:F186) -> 8 | P16: =(SUM('Training pairs'!I179:I186)-SUM('Training pairs'!F179:F186)*SUM('Training pairs'!G179:G186)/COUNT('Training pairs'!F179:F186))/(SUM('Training pairs'!H179:H186)-SUM('Training pairs'!F179:F186)^2/COUNT('Training pairs'!F179:F186)) -> 0.60069365 | Q16: =AVERAGE('Training pairs'!G179:G186)-P16*AVERAGE('Training pairs'!F179:F186) -> -1.6931367 | R16: 1.7438949 | S16: =Q16+P16*R16 -> -0.64559015 | T16: =(H16+N16)/2 -> 0.03941255 | U16: 45443 | V16: 45401 | W16: https://alfred.stlouisfed.org/graph/alfredgraph.csv?id=PCENDC96&cosd=2021-01-01&coed=2026-04-01&vintage_date=2024-05-31
B17: 12 | C17: Grooming | D17: organic_volume_growth | E17: 45473 | F17: 45471 | G17: 2 | H17: =AVERAGE('PG facts'!D42,'PG facts'!D49,'PG facts'!D56,'PG facts'!D63) -> 0 | I17: ='PG facts'!D63 -> 2 | J17: =COUNT('Training pairs'!F187:F195) -> 9 | K17: =(SUM('Training pairs'!I187:I195)-SUM('Training pairs'!F187:F195)*SUM('Training pairs'!G187:G195)/COUNT('Training pairs'!F187:F195))/(SUM('Training pairs'!H187:H195)-SUM('Training pairs'!F187:F195)^2/COUNT('Training pairs'!F187:F195)) -> 1.1592507 | L17: =AVERAGE('Training pairs'!G187:G195)-K17*AVERAGE('Training pairs'!F187:F195) -> -1.9703412 | M17: =(SUM('Target months'!H39:H41)/SUM('Target months'!F39:F41)-1)*100 -> 1.5780382 | N17: =L17+K17*M17 -> -0.14099933 | O17: =COUNT('Training pairs'!F196:F203) -> 8 | P17: =(SUM('Training pairs'!I196:I203)-SUM('Training pairs'!F196:F203)*SUM('Training pairs'!G196:G203)/COUNT('Training pairs'!F196:F203))/(SUM('Training pairs'!H196:H203)-SUM('Training pairs'!F196:F203)^2/COUNT('Training pairs'!F196:F203)) -> 0.60069365 | Q17: =AVERAGE('Training pairs'!G196:G203)-P17*AVERAGE('Training pairs'!F196:F203) -> -1.6931367 | R17: 1.6317086 | S17: =Q17+P17*R17 -> -0.7129797 | T17: =(H17+N17)/2 -> -0.070499663 | U17: 45471 | V17: 45401 | W17: https://alfred.stlouisfed.org/graph/alfredgraph.csv?id=PCENDC96&cosd=2021-01-01&coed=2026-04-01&vintage_date=2024-06-28
B18: 13 | C18: Grooming | D18: organic_volume_growth | E18: 45473 | F18: 45499 | G18: 3 | H18: =AVERAGE('PG facts'!D42,'PG facts'!D49,'PG facts'!D56,'PG facts'!D63) -> 0 | I18: ='PG facts'!D63 -> 2 | J18: =COUNT('Training pairs'!F204:F212) -> 9 | K18: =(SUM('Training pairs'!I204:I212)-SUM('Training pairs'!F204:F212)*SUM('Training pairs'!G204:G212)/COUNT('Training pairs'!F204:F212))/(SUM('Training pairs'!H204:H212)-SUM('Training pairs'!F204:F212)^2/COUNT('Training pairs'!F204:F212)) -> 1.1592507 | L18: =AVERAGE('Training pairs'!G204:G212)-K18*AVERAGE('Training pairs'!F204:F212) -> -1.9703412 | M18: =(SUM('Target months'!H42:H44)/SUM('Target months'!F42:F44)-1)*100 -> 1.7459001 | N18: =L18+K18*M18 -> 0.053594674 | O18: =COUNT('Training pairs'!F213:F220) -> 8 | P18: =(SUM('Training pairs'!I213:I220)-SUM('Training pairs'!F213:F220)*SUM('Training pairs'!G213:G220)/COUNT('Training pairs'!F213:F220))/(SUM('Training pairs'!H213:H220)-SUM('Training pairs'!F213:F220)^2/COUNT('Training pairs'!F213:F220)) -> 0.60069365 | Q18: =AVERAGE('Training pairs'!G213:G220)-P18*AVERAGE('Training pairs'!F213:F220) -> -1.6931367 | R18: 1.6317086 | S18: =Q18+P18*R18 -> -0.7129797 | T18: =(H18+N18)/2 -> 0.026797337 | U18: 45499 | V18: 45401 | W18: https://alfred.stlouisfed.org/graph/alfredgraph.csv?id=PCENDC96&cosd=2021-01-01&coed=2026-04-01&vintage_date=2024-07-26
B19: 14 | C19: Grooming | D19: organic_volume_growth | E19: 45473 | F19: 45502 | G19: 3 | H19: =AVERAGE('PG facts'!D42,'PG facts'!D49,'PG facts'!D56,'PG facts'!D63) -> 0 | I19: ='PG facts'!D63 -> 2 | J19: =COUNT('Training pairs'!F221:F229) -> 9 | K19: =(SUM('Training pairs'!I221:I229)-SUM('Training pairs'!F221:F229)*SUM('Training pairs'!G221:G229)/COUNT('Training pairs'!F221:F229))/(SUM('Training pairs'!H221:H229)-SUM('Training pairs'!F221:F229)^2/COUNT('Training pairs'!F221:F229)) -> 1.1592507 | L19: =AVERAGE('Training pairs'!G221:G229)-K19*AVERAGE('Training pairs'!F221:F229) -> -1.9703412 | M19: =(SUM('Target months'!H45:H47)/SUM('Target months'!F45:F47)-1)*100 -> 1.7459001 | N19: =L19+K19*M19 -> 0.053594674 | O19: =COUNT('Training pairs'!F230:F237) -> 8 | P19: =(SUM('Training pairs'!I230:I237)-SUM('Training pairs'!F230:F237)*SUM('Training pairs'!G230:G237)/COUNT('Training pairs'!F230:F237))/(SUM('Training pairs'!H230:H237)-SUM('Training pairs'!F230:F237)^2/COUNT('Training pairs'!F230:F237)) -> 0.60069365 | Q19: =AVERAGE('Training pairs'!G230:G237)-P19*AVERAGE('Training pairs'!F230:F237) -> -1.6931367 | R19: 1.6317086 | S19: =Q19+P19*R19 -> -0.7129797 | T19: =(H19+N19)/2 -> 0.026797337 | U19: 45499 | V19: 45401 | W19: https://alfred.stlouisfed.org/graph/alfredgraph.csv?id=PCENDC96&cosd=2021-01-01&coed=2026-04-01&vintage_date=2024-07-26
B20: 15 | C20: Health Care | D20: organic_volume_growth | E20: 45473 | F20: 45383 | G20: 0 | H20: =AVERAGE('PG facts'!D36,'PG facts'!D43,'PG facts'!D50,'PG facts'!D57) -> -1 | I20: ='PG facts'!D57 -> -4 | J20: =COUNT('Training pairs'!F238:F245) -> 8 | K20: =(SUM('Training pairs'!I238:I245)-SUM('Training pairs'!F238:F245)*SUM('Training pairs'!G238:G245)/COUNT('Training pairs'!F238:F245))/(SUM('Training pairs'!H238:H245)-SUM('Training pairs'!F238:F245)^2/COUNT('Training pairs'!F238:F245)) -> 1.4919507 | L20: =AVERAGE('Training pairs'!G238:G245)-K20*AVERAGE('Training pairs'!F238:F245) -> -0.97562448 | M20: =(SUM('Target months'!H48:H50)/SUM('Target months'!F48:F50)-1)*100 -> 1.6699249 | N20: =L20+K20*M20 -> 1.5158211 | O20: ="n.a." -> n.a. | P20: ="n.a." -> n.a. | Q20: ="n.a." -> n.a. | R20: n.a. | S20: ="n.a." -> n.a. | T20: =(H20+N20)/2 -> 0.25791056 | U20: 45383 | V20: 45314 | W20: https://alfred.stlouisfed.org/graph/alfredgraph.csv?id=PCENDC96&cosd=2021-01-01&coed=2026-04-01&vintage_date=2024-04-01
B21: 16 | C21: Health Care | D21: organic_volume_growth | E21: 45473 | F21: 45401 | G21: 0 | H21: =AVERAGE('PG facts'!D43,'PG facts'!D50,'PG facts'!D57,'PG facts'!D64) -> -2.25 | I21: ='PG facts'!D64 -> -4 | J21: =COUNT('Training pairs'!F253:F260) -> 8 | K21: =(SUM('Training pairs'!I253:I260)-SUM('Training pairs'!F253:F260)*SUM('Training pairs'!G253:G260)/COUNT('Training pairs'!F253:F260))/(SUM('Training pairs'!H253:H260)-SUM('Training pairs'!F253:F260)^2/COUNT('Training pairs'!F253:F260)) -> 1.4919507 | L21: =AVERAGE('Training pairs'!G253:G260)-K21*AVERAGE('Training pairs'!F253:F260) -> -0.97562448 | M21: =(SUM('Target months'!H51:H53)/SUM('Target months'!F51:F53)-1)*100 -> 1.6699249 | N21: =L21+K21*M21 -> 1.5158211 | O21: =COUNT('Training pairs'!F261:F268) -> 8 | P21: =(SUM('Training pairs'!I261:I268)-SUM('Training pairs'!F261:F268)*SUM('Training pairs'!G261:G268)/COUNT('Training pairs'!F261:F268))/(SUM('Training pairs'!H261:H268)-SUM('Training pairs'!F261:F268)^2/COUNT('Training pairs'!F261:F268)) -> -0.35458458 | Q21: =AVERAGE('Training pairs'!G261:G268)-P21*AVERAGE('Training pairs'!F261:F268) -> -1.11342 | R21: n.a. | S21: ="n.a." -> n.a. | T21: =(H21+N21)/2 -> -0.36708944 | U21: 45383 | V21: 45401 | W21: https://alfred.stlouisfed.org/graph/alfredgraph.csv?id=PCENDC96&cosd=2021-01-01&coed=2026-04-01&vintage_date=2024-04-01
